2022-01-13 09:51:57,764 <ERROR> :  occered at executeGetRequest <class 'ValueError'>1
2022-01-13 09:51:57,764 <ERROR> : Traceback (most recent call last):
  File "./py/connect.py", line 195, in executeGetRequest
    root = lxml.html.fromstring(html)
  File "C:\Users\waard\anaconda3\lib\site-packages\lxml\html\__init__.py", line 875, in fromstring
    doc = document_fromstring(html, parser=parser, base_url=base_url, **kw)
  File "C:\Users\waard\anaconda3\lib\site-packages\lxml\html\__init__.py", line 761, in document_fromstring
    value = etree.fromstring(html, parser, **kw)
  File "src/lxml/etree.pyx", line 3237, in lxml.etree.fromstring
  File "src/lxml/parser.pxi", line 1891, in lxml.etree._parseMemoryDocument
ValueError: Unicode strings with encoding declaration are not supported. Please use bytes input or XML fragments without declaration.

2022-01-13 09:52:56,835 <ERROR> :  occered at executeGetRequest <class 'requests.exceptions.ReadTimeout'>
2022-01-13 09:52:56,835 <ERROR> : Traceback (most recent call last):
  File "C:\Users\waard\anaconda3\lib\site-packages\urllib3\connectionpool.py", line 445, in _make_request
    six.raise_from(e, None)
  File "<string>", line 3, in raise_from
  File "C:\Users\waard\anaconda3\lib\site-packages\urllib3\connectionpool.py", line 440, in _make_request
    httplib_response = conn.getresponse()
  File "C:\Users\waard\anaconda3\lib\http\client.py", line 1344, in getresponse
    response.begin()
  File "C:\Users\waard\anaconda3\lib\http\client.py", line 307, in begin
    version, status, reason = self._read_status()
  File "C:\Users\waard\anaconda3\lib\http\client.py", line 268, in _read_status
    line = str(self.fp.readline(_MAXLINE + 1), "iso-8859-1")
  File "C:\Users\waard\anaconda3\lib\socket.py", line 669, in readinto
    return self._sock.recv_into(b)
  File "C:\Users\waard\anaconda3\lib\ssl.py", line 1241, in recv_into
    return self.read(nbytes, buffer)
  File "C:\Users\waard\anaconda3\lib\ssl.py", line 1099, in read
    return self._sslobj.read(len, buffer)
socket.timeout: The read operation timed out

During handling of the above exception, another exception occurred:

Traceback (most recent call last):
  File "C:\Users\waard\anaconda3\lib\site-packages\requests\adapters.py", line 439, in send
    resp = conn.urlopen(
  File "C:\Users\waard\anaconda3\lib\site-packages\urllib3\connectionpool.py", line 755, in urlopen
    retries = retries.increment(
  File "C:\Users\waard\anaconda3\lib\site-packages\urllib3\util\retry.py", line 532, in increment
    raise six.reraise(type(error), error, _stacktrace)
  File "C:\Users\waard\anaconda3\lib\site-packages\urllib3\packages\six.py", line 770, in reraise
    raise value
  File "C:\Users\waard\anaconda3\lib\site-packages\urllib3\connectionpool.py", line 699, in urlopen
    httplib_response = self._make_request(
  File "C:\Users\waard\anaconda3\lib\site-packages\urllib3\connectionpool.py", line 447, in _make_request
    self._raise_timeout(err=e, url=url, timeout_value=read_timeout)
  File "C:\Users\waard\anaconda3\lib\site-packages\urllib3\connectionpool.py", line 336, in _raise_timeout
    raise ReadTimeoutError(
urllib3.exceptions.ReadTimeoutError: HTTPSConnectionPool(host='zozo.jp', port=443): Read timed out. (read timeout=7.5)

During handling of the above exception, another exception occurred:

Traceback (most recent call last):
  File "./py/connect.py", line 187, in executeGetRequest
    res = requests.get(arrayList['crawlingurl'], timeout=(3.0, 7.5))
  File "C:\Users\waard\anaconda3\lib\site-packages\requests\api.py", line 76, in get
    return request('get', url, params=params, **kwargs)
  File "C:\Users\waard\anaconda3\lib\site-packages\requests\api.py", line 61, in request
    return session.request(method=method, url=url, **kwargs)
  File "C:\Users\waard\anaconda3\lib\site-packages\requests\sessions.py", line 542, in request
    resp = self.send(prep, **send_kwargs)
  File "C:\Users\waard\anaconda3\lib\site-packages\requests\sessions.py", line 655, in send
    r = adapter.send(request, **kwargs)
  File "C:\Users\waard\anaconda3\lib\site-packages\requests\adapters.py", line 529, in send
    raise ReadTimeout(e, request=request)
requests.exceptions.ReadTimeout: HTTPSConnectionPool(host='zozo.jp', port=443): Read timed out. (read timeout=7.5)

2022-01-13 09:53:04,410 <ERROR> :  occered at executeGetRequest <class 'requests.exceptions.ReadTimeout'>
2022-01-13 09:53:04,410 <ERROR> : Traceback (most recent call last):
  File "C:\Users\waard\anaconda3\lib\site-packages\urllib3\connectionpool.py", line 445, in _make_request
    six.raise_from(e, None)
  File "<string>", line 3, in raise_from
  File "C:\Users\waard\anaconda3\lib\site-packages\urllib3\connectionpool.py", line 440, in _make_request
    httplib_response = conn.getresponse()
  File "C:\Users\waard\anaconda3\lib\http\client.py", line 1344, in getresponse
    response.begin()
  File "C:\Users\waard\anaconda3\lib\http\client.py", line 307, in begin
    version, status, reason = self._read_status()
  File "C:\Users\waard\anaconda3\lib\http\client.py", line 268, in _read_status
    line = str(self.fp.readline(_MAXLINE + 1), "iso-8859-1")
  File "C:\Users\waard\anaconda3\lib\socket.py", line 669, in readinto
    return self._sock.recv_into(b)
  File "C:\Users\waard\anaconda3\lib\ssl.py", line 1241, in recv_into
    return self.read(nbytes, buffer)
  File "C:\Users\waard\anaconda3\lib\ssl.py", line 1099, in read
    return self._sslobj.read(len, buffer)
socket.timeout: The read operation timed out

During handling of the above exception, another exception occurred:

Traceback (most recent call last):
  File "C:\Users\waard\anaconda3\lib\site-packages\requests\adapters.py", line 439, in send
    resp = conn.urlopen(
  File "C:\Users\waard\anaconda3\lib\site-packages\urllib3\connectionpool.py", line 755, in urlopen
    retries = retries.increment(
  File "C:\Users\waard\anaconda3\lib\site-packages\urllib3\util\retry.py", line 532, in increment
    raise six.reraise(type(error), error, _stacktrace)
  File "C:\Users\waard\anaconda3\lib\site-packages\urllib3\packages\six.py", line 770, in reraise
    raise value
  File "C:\Users\waard\anaconda3\lib\site-packages\urllib3\connectionpool.py", line 699, in urlopen
    httplib_response = self._make_request(
  File "C:\Users\waard\anaconda3\lib\site-packages\urllib3\connectionpool.py", line 447, in _make_request
    self._raise_timeout(err=e, url=url, timeout_value=read_timeout)
  File "C:\Users\waard\anaconda3\lib\site-packages\urllib3\connectionpool.py", line 336, in _raise_timeout
    raise ReadTimeoutError(
urllib3.exceptions.ReadTimeoutError: HTTPSConnectionPool(host='zozo.jp', port=443): Read timed out. (read timeout=7.5)

During handling of the above exception, another exception occurred:

Traceback (most recent call last):
  File "./py/connect.py", line 187, in executeGetRequest
    res = requests.get(arrayList['crawlingurl'], timeout=(3.0, 7.5))
  File "C:\Users\waard\anaconda3\lib\site-packages\requests\api.py", line 76, in get
    return request('get', url, params=params, **kwargs)
  File "C:\Users\waard\anaconda3\lib\site-packages\requests\api.py", line 61, in request
    return session.request(method=method, url=url, **kwargs)
  File "C:\Users\waard\anaconda3\lib\site-packages\requests\sessions.py", line 542, in request
    resp = self.send(prep, **send_kwargs)
  File "C:\Users\waard\anaconda3\lib\site-packages\requests\sessions.py", line 655, in send
    r = adapter.send(request, **kwargs)
  File "C:\Users\waard\anaconda3\lib\site-packages\requests\adapters.py", line 529, in send
    raise ReadTimeout(e, request=request)
requests.exceptions.ReadTimeout: HTTPSConnectionPool(host='zozo.jp', port=443): Read timed out. (read timeout=7.5)

2022-01-13 09:53:11,992 <ERROR> :  occered at executeGetRequest <class 'requests.exceptions.ReadTimeout'>
2022-01-13 09:53:11,992 <ERROR> : Traceback (most recent call last):
  File "C:\Users\waard\anaconda3\lib\site-packages\urllib3\connectionpool.py", line 445, in _make_request
    six.raise_from(e, None)
  File "<string>", line 3, in raise_from
  File "C:\Users\waard\anaconda3\lib\site-packages\urllib3\connectionpool.py", line 440, in _make_request
    httplib_response = conn.getresponse()
  File "C:\Users\waard\anaconda3\lib\http\client.py", line 1344, in getresponse
    response.begin()
  File "C:\Users\waard\anaconda3\lib\http\client.py", line 307, in begin
    version, status, reason = self._read_status()
  File "C:\Users\waard\anaconda3\lib\http\client.py", line 268, in _read_status
    line = str(self.fp.readline(_MAXLINE + 1), "iso-8859-1")
  File "C:\Users\waard\anaconda3\lib\socket.py", line 669, in readinto
    return self._sock.recv_into(b)
  File "C:\Users\waard\anaconda3\lib\ssl.py", line 1241, in recv_into
    return self.read(nbytes, buffer)
  File "C:\Users\waard\anaconda3\lib\ssl.py", line 1099, in read
    return self._sslobj.read(len, buffer)
socket.timeout: The read operation timed out

During handling of the above exception, another exception occurred:

Traceback (most recent call last):
  File "C:\Users\waard\anaconda3\lib\site-packages\requests\adapters.py", line 439, in send
    resp = conn.urlopen(
  File "C:\Users\waard\anaconda3\lib\site-packages\urllib3\connectionpool.py", line 755, in urlopen
    retries = retries.increment(
  File "C:\Users\waard\anaconda3\lib\site-packages\urllib3\util\retry.py", line 532, in increment
    raise six.reraise(type(error), error, _stacktrace)
  File "C:\Users\waard\anaconda3\lib\site-packages\urllib3\packages\six.py", line 770, in reraise
    raise value
  File "C:\Users\waard\anaconda3\lib\site-packages\urllib3\connectionpool.py", line 699, in urlopen
    httplib_response = self._make_request(
  File "C:\Users\waard\anaconda3\lib\site-packages\urllib3\connectionpool.py", line 447, in _make_request
    self._raise_timeout(err=e, url=url, timeout_value=read_timeout)
  File "C:\Users\waard\anaconda3\lib\site-packages\urllib3\connectionpool.py", line 336, in _raise_timeout
    raise ReadTimeoutError(
urllib3.exceptions.ReadTimeoutError: HTTPSConnectionPool(host='zozo.jp', port=443): Read timed out. (read timeout=7.5)

During handling of the above exception, another exception occurred:

Traceback (most recent call last):
  File "./py/connect.py", line 187, in executeGetRequest
    res = requests.get(arrayList['crawlingurl'], timeout=(3.0, 7.5))
  File "C:\Users\waard\anaconda3\lib\site-packages\requests\api.py", line 76, in get
    return request('get', url, params=params, **kwargs)
  File "C:\Users\waard\anaconda3\lib\site-packages\requests\api.py", line 61, in request
    return session.request(method=method, url=url, **kwargs)
  File "C:\Users\waard\anaconda3\lib\site-packages\requests\sessions.py", line 542, in request
    resp = self.send(prep, **send_kwargs)
  File "C:\Users\waard\anaconda3\lib\site-packages\requests\sessions.py", line 655, in send
    r = adapter.send(request, **kwargs)
  File "C:\Users\waard\anaconda3\lib\site-packages\requests\adapters.py", line 529, in send
    raise ReadTimeout(e, request=request)
requests.exceptions.ReadTimeout: HTTPSConnectionPool(host='zozo.jp', port=443): Read timed out. (read timeout=7.5)

2022-01-13 09:53:11,993 <ERROR> :  occered at executeGetRequest Max retries exceeded with urlhttps://zozo.jp/brand/nike/shoes/sneakers/
2022-01-13 09:53:12,639 <ERROR> :  occered at executeGetRequest requests failed:https://www.jiji.com/jc/c?g=pol
2022-01-13 09:53:16,097 <ERROR> :  occered at executeGetRequest requests failed:https://www.jiji.com/jc/c?g=pol
2022-01-13 09:53:19,571 <ERROR> :  occered at executeGetRequest requests failed:https://www.jiji.com/jc/c?g=pol
2022-01-13 09:53:22,578 <ERROR> :  occered at executeGetRequest Max retries exceeded with urlhttps://www.jiji.com/jc/c?g=pol
2022-01-13 14:04:33,413 <ERROR> :  occered at executeGetRequest <class 'ValueError'>1
2022-01-13 14:04:33,413 <ERROR> : Traceback (most recent call last):
  File "./py/connect.py", line 195, in executeGetRequest
    root = lxml.html.fromstring(html)
  File "C:\Users\waard\anaconda3\lib\site-packages\lxml\html\__init__.py", line 875, in fromstring
    doc = document_fromstring(html, parser=parser, base_url=base_url, **kw)
  File "C:\Users\waard\anaconda3\lib\site-packages\lxml\html\__init__.py", line 761, in document_fromstring
    value = etree.fromstring(html, parser, **kw)
  File "src/lxml/etree.pyx", line 3237, in lxml.etree.fromstring
  File "src/lxml/parser.pxi", line 1891, in lxml.etree._parseMemoryDocument
ValueError: Unicode strings with encoding declaration are not supported. Please use bytes input or XML fragments without declaration.

2022-01-13 14:05:51,667 <ERROR> :  occered at executeGetRequest <class 'requests.exceptions.ReadTimeout'>
2022-01-13 14:05:51,667 <ERROR> : Traceback (most recent call last):
  File "C:\Users\waard\anaconda3\lib\site-packages\urllib3\connectionpool.py", line 445, in _make_request
    six.raise_from(e, None)
  File "<string>", line 3, in raise_from
  File "C:\Users\waard\anaconda3\lib\site-packages\urllib3\connectionpool.py", line 440, in _make_request
    httplib_response = conn.getresponse()
  File "C:\Users\waard\anaconda3\lib\http\client.py", line 1344, in getresponse
    response.begin()
  File "C:\Users\waard\anaconda3\lib\http\client.py", line 307, in begin
    version, status, reason = self._read_status()
  File "C:\Users\waard\anaconda3\lib\http\client.py", line 268, in _read_status
    line = str(self.fp.readline(_MAXLINE + 1), "iso-8859-1")
  File "C:\Users\waard\anaconda3\lib\socket.py", line 669, in readinto
    return self._sock.recv_into(b)
  File "C:\Users\waard\anaconda3\lib\ssl.py", line 1241, in recv_into
    return self.read(nbytes, buffer)
  File "C:\Users\waard\anaconda3\lib\ssl.py", line 1099, in read
    return self._sslobj.read(len, buffer)
socket.timeout: The read operation timed out

During handling of the above exception, another exception occurred:

Traceback (most recent call last):
  File "C:\Users\waard\anaconda3\lib\site-packages\requests\adapters.py", line 439, in send
    resp = conn.urlopen(
  File "C:\Users\waard\anaconda3\lib\site-packages\urllib3\connectionpool.py", line 755, in urlopen
    retries = retries.increment(
  File "C:\Users\waard\anaconda3\lib\site-packages\urllib3\util\retry.py", line 532, in increment
    raise six.reraise(type(error), error, _stacktrace)
  File "C:\Users\waard\anaconda3\lib\site-packages\urllib3\packages\six.py", line 770, in reraise
    raise value
  File "C:\Users\waard\anaconda3\lib\site-packages\urllib3\connectionpool.py", line 699, in urlopen
    httplib_response = self._make_request(
  File "C:\Users\waard\anaconda3\lib\site-packages\urllib3\connectionpool.py", line 447, in _make_request
    self._raise_timeout(err=e, url=url, timeout_value=read_timeout)
  File "C:\Users\waard\anaconda3\lib\site-packages\urllib3\connectionpool.py", line 336, in _raise_timeout
    raise ReadTimeoutError(
urllib3.exceptions.ReadTimeoutError: HTTPSConnectionPool(host='zozo.jp', port=443): Read timed out. (read timeout=7.5)

During handling of the above exception, another exception occurred:

Traceback (most recent call last):
  File "./py/connect.py", line 187, in executeGetRequest
    res = requests.get(arrayList['crawlingurl'], timeout=(3.0, 7.5))
  File "C:\Users\waard\anaconda3\lib\site-packages\requests\api.py", line 76, in get
    return request('get', url, params=params, **kwargs)
  File "C:\Users\waard\anaconda3\lib\site-packages\requests\api.py", line 61, in request
    return session.request(method=method, url=url, **kwargs)
  File "C:\Users\waard\anaconda3\lib\site-packages\requests\sessions.py", line 542, in request
    resp = self.send(prep, **send_kwargs)
  File "C:\Users\waard\anaconda3\lib\site-packages\requests\sessions.py", line 655, in send
    r = adapter.send(request, **kwargs)
  File "C:\Users\waard\anaconda3\lib\site-packages\requests\adapters.py", line 529, in send
    raise ReadTimeout(e, request=request)
requests.exceptions.ReadTimeout: HTTPSConnectionPool(host='zozo.jp', port=443): Read timed out. (read timeout=7.5)

2022-01-13 14:05:59,225 <ERROR> :  occered at executeGetRequest <class 'requests.exceptions.ReadTimeout'>
2022-01-13 14:05:59,227 <ERROR> : Traceback (most recent call last):
  File "C:\Users\waard\anaconda3\lib\site-packages\urllib3\connectionpool.py", line 445, in _make_request
    six.raise_from(e, None)
  File "<string>", line 3, in raise_from
  File "C:\Users\waard\anaconda3\lib\site-packages\urllib3\connectionpool.py", line 440, in _make_request
    httplib_response = conn.getresponse()
  File "C:\Users\waard\anaconda3\lib\http\client.py", line 1344, in getresponse
    response.begin()
  File "C:\Users\waard\anaconda3\lib\http\client.py", line 307, in begin
    version, status, reason = self._read_status()
  File "C:\Users\waard\anaconda3\lib\http\client.py", line 268, in _read_status
    line = str(self.fp.readline(_MAXLINE + 1), "iso-8859-1")
  File "C:\Users\waard\anaconda3\lib\socket.py", line 669, in readinto
    return self._sock.recv_into(b)
  File "C:\Users\waard\anaconda3\lib\ssl.py", line 1241, in recv_into
    return self.read(nbytes, buffer)
  File "C:\Users\waard\anaconda3\lib\ssl.py", line 1099, in read
    return self._sslobj.read(len, buffer)
socket.timeout: The read operation timed out

During handling of the above exception, another exception occurred:

Traceback (most recent call last):
  File "C:\Users\waard\anaconda3\lib\site-packages\requests\adapters.py", line 439, in send
    resp = conn.urlopen(
  File "C:\Users\waard\anaconda3\lib\site-packages\urllib3\connectionpool.py", line 755, in urlopen
    retries = retries.increment(
  File "C:\Users\waard\anaconda3\lib\site-packages\urllib3\util\retry.py", line 532, in increment
    raise six.reraise(type(error), error, _stacktrace)
  File "C:\Users\waard\anaconda3\lib\site-packages\urllib3\packages\six.py", line 770, in reraise
    raise value
  File "C:\Users\waard\anaconda3\lib\site-packages\urllib3\connectionpool.py", line 699, in urlopen
    httplib_response = self._make_request(
  File "C:\Users\waard\anaconda3\lib\site-packages\urllib3\connectionpool.py", line 447, in _make_request
    self._raise_timeout(err=e, url=url, timeout_value=read_timeout)
  File "C:\Users\waard\anaconda3\lib\site-packages\urllib3\connectionpool.py", line 336, in _raise_timeout
    raise ReadTimeoutError(
urllib3.exceptions.ReadTimeoutError: HTTPSConnectionPool(host='zozo.jp', port=443): Read timed out. (read timeout=7.5)

During handling of the above exception, another exception occurred:

Traceback (most recent call last):
  File "./py/connect.py", line 187, in executeGetRequest
    res = requests.get(arrayList['crawlingurl'], timeout=(3.0, 7.5))
  File "C:\Users\waard\anaconda3\lib\site-packages\requests\api.py", line 76, in get
    return request('get', url, params=params, **kwargs)
  File "C:\Users\waard\anaconda3\lib\site-packages\requests\api.py", line 61, in request
    return session.request(method=method, url=url, **kwargs)
  File "C:\Users\waard\anaconda3\lib\site-packages\requests\sessions.py", line 542, in request
    resp = self.send(prep, **send_kwargs)
  File "C:\Users\waard\anaconda3\lib\site-packages\requests\sessions.py", line 655, in send
    r = adapter.send(request, **kwargs)
  File "C:\Users\waard\anaconda3\lib\site-packages\requests\adapters.py", line 529, in send
    raise ReadTimeout(e, request=request)
requests.exceptions.ReadTimeout: HTTPSConnectionPool(host='zozo.jp', port=443): Read timed out. (read timeout=7.5)

2022-01-13 14:06:06,798 <ERROR> :  occered at executeGetRequest <class 'requests.exceptions.ReadTimeout'>
2022-01-13 14:06:06,798 <ERROR> : Traceback (most recent call last):
  File "C:\Users\waard\anaconda3\lib\site-packages\urllib3\connectionpool.py", line 445, in _make_request
    six.raise_from(e, None)
  File "<string>", line 3, in raise_from
  File "C:\Users\waard\anaconda3\lib\site-packages\urllib3\connectionpool.py", line 440, in _make_request
    httplib_response = conn.getresponse()
  File "C:\Users\waard\anaconda3\lib\http\client.py", line 1344, in getresponse
    response.begin()
  File "C:\Users\waard\anaconda3\lib\http\client.py", line 307, in begin
    version, status, reason = self._read_status()
  File "C:\Users\waard\anaconda3\lib\http\client.py", line 268, in _read_status
    line = str(self.fp.readline(_MAXLINE + 1), "iso-8859-1")
  File "C:\Users\waard\anaconda3\lib\socket.py", line 669, in readinto
    return self._sock.recv_into(b)
  File "C:\Users\waard\anaconda3\lib\ssl.py", line 1241, in recv_into
    return self.read(nbytes, buffer)
  File "C:\Users\waard\anaconda3\lib\ssl.py", line 1099, in read
    return self._sslobj.read(len, buffer)
socket.timeout: The read operation timed out

During handling of the above exception, another exception occurred:

Traceback (most recent call last):
  File "C:\Users\waard\anaconda3\lib\site-packages\requests\adapters.py", line 439, in send
    resp = conn.urlopen(
  File "C:\Users\waard\anaconda3\lib\site-packages\urllib3\connectionpool.py", line 755, in urlopen
    retries = retries.increment(
  File "C:\Users\waard\anaconda3\lib\site-packages\urllib3\util\retry.py", line 532, in increment
    raise six.reraise(type(error), error, _stacktrace)
  File "C:\Users\waard\anaconda3\lib\site-packages\urllib3\packages\six.py", line 770, in reraise
    raise value
  File "C:\Users\waard\anaconda3\lib\site-packages\urllib3\connectionpool.py", line 699, in urlopen
    httplib_response = self._make_request(
  File "C:\Users\waard\anaconda3\lib\site-packages\urllib3\connectionpool.py", line 447, in _make_request
    self._raise_timeout(err=e, url=url, timeout_value=read_timeout)
  File "C:\Users\waard\anaconda3\lib\site-packages\urllib3\connectionpool.py", line 336, in _raise_timeout
    raise ReadTimeoutError(
urllib3.exceptions.ReadTimeoutError: HTTPSConnectionPool(host='zozo.jp', port=443): Read timed out. (read timeout=7.5)

During handling of the above exception, another exception occurred:

Traceback (most recent call last):
  File "./py/connect.py", line 187, in executeGetRequest
    res = requests.get(arrayList['crawlingurl'], timeout=(3.0, 7.5))
  File "C:\Users\waard\anaconda3\lib\site-packages\requests\api.py", line 76, in get
    return request('get', url, params=params, **kwargs)
  File "C:\Users\waard\anaconda3\lib\site-packages\requests\api.py", line 61, in request
    return session.request(method=method, url=url, **kwargs)
  File "C:\Users\waard\anaconda3\lib\site-packages\requests\sessions.py", line 542, in request
    resp = self.send(prep, **send_kwargs)
  File "C:\Users\waard\anaconda3\lib\site-packages\requests\sessions.py", line 655, in send
    r = adapter.send(request, **kwargs)
  File "C:\Users\waard\anaconda3\lib\site-packages\requests\adapters.py", line 529, in send
    raise ReadTimeout(e, request=request)
requests.exceptions.ReadTimeout: HTTPSConnectionPool(host='zozo.jp', port=443): Read timed out. (read timeout=7.5)

2022-01-13 14:06:06,798 <ERROR> :  occered at executeGetRequest Max retries exceeded with urlhttps://zozo.jp/brand/nike/shoes/sneakers/
2022-01-13 14:06:07,495 <ERROR> :  occered at executeGetRequest requests failed:https://www.jiji.com/jc/c?g=pol
2022-01-13 14:06:11,198 <ERROR> :  occered at executeGetRequest requests failed:https://www.jiji.com/jc/c?g=pol
2022-01-13 14:06:14,767 <ERROR> :  occered at executeGetRequest requests failed:https://www.jiji.com/jc/c?g=pol
2022-01-13 14:06:17,776 <ERROR> :  occered at executeGetRequest Max retries exceeded with urlhttps://www.jiji.com/jc/c?g=pol
