2022-01-25 01:47:29,785 <ERROR> :  occered at executeGetRequest <class 'ValueError'>1
2022-01-25 01:47:29,786 <ERROR> : Traceback (most recent call last):
  File "./py/connect.py", line 207, in executeGetRequest
    root = lxml.html.fromstring(html)
  File "C:\Users\waard\Desktop\my-app\py\env_v3.8.12\lib\site-packages\lxml\html\__init__.py", line 875, in fromstring
    doc = document_fromstring(html, parser=parser, base_url=base_url, **kw)
  File "C:\Users\waard\Desktop\my-app\py\env_v3.8.12\lib\site-packages\lxml\html\__init__.py", line 761, in document_fromstring
    value = etree.fromstring(html, parser, **kw)
  File "src\lxml\etree.pyx", line 3252, in lxml.etree.fromstring
  File "src\lxml\parser.pxi", line 1907, in lxml.etree._parseMemoryDocument
ValueError: Unicode strings with encoding declaration are not supported. Please use bytes input or XML fragments without declaration.

2022-01-25 01:48:03,087 <ERROR> :  occered at executeGetRequest requests failed:https://www.jiji.com/jc/c?g=pol
2022-01-25 01:48:06,416 <ERROR> :  occered at executeGetRequest requests failed:https://www.jiji.com/jc/c?g=pol
2022-01-25 01:48:09,727 <ERROR> :  occered at executeGetRequest requests failed:https://www.jiji.com/jc/c?g=pol
2022-01-25 01:48:12,728 <ERROR> :  occered at executeGetRequest Max retries exceeded with urlhttps://www.jiji.com/jc/c?g=pol
2022-01-25 22:50:43,878 <ERROR> :  occered at executeGetRequest <class 'ValueError'>1
2022-01-25 22:50:43,878 <ERROR> : Traceback (most recent call last):
  File "./py/connect.py", line 208, in executeGetRequest
    root = lxml.html.fromstring(html)
  File "C:\Users\waard\Desktop\my-app\py\env_v3.8.12\lib\site-packages\lxml\html\__init__.py", line 875, in fromstring
    doc = document_fromstring(html, parser=parser, base_url=base_url, **kw)
  File "C:\Users\waard\Desktop\my-app\py\env_v3.8.12\lib\site-packages\lxml\html\__init__.py", line 761, in document_fromstring
    value = etree.fromstring(html, parser, **kw)
  File "src\lxml\etree.pyx", line 3252, in lxml.etree.fromstring
  File "src\lxml\parser.pxi", line 1907, in lxml.etree._parseMemoryDocument
ValueError: Unicode strings with encoding declaration are not supported. Please use bytes input or XML fragments without declaration.

2022-01-25 22:51:32,801 <ERROR> :  occered at executeGetRequest <class 'requests.exceptions.ReadTimeout'>
2022-01-25 22:51:32,801 <ERROR> : Traceback (most recent call last):
  File "C:\Users\waard\Desktop\my-app\py\env_v3.8.12\lib\site-packages\urllib3\connectionpool.py", line 449, in _make_request
    six.raise_from(e, None)
  File "<string>", line 3, in raise_from
  File "C:\Users\waard\Desktop\my-app\py\env_v3.8.12\lib\site-packages\urllib3\connectionpool.py", line 444, in _make_request
    httplib_response = conn.getresponse()
  File "C:\Users\waard\anaconda3\lib\http\client.py", line 1348, in getresponse
    response.begin()
  File "C:\Users\waard\anaconda3\lib\http\client.py", line 316, in begin
    version, status, reason = self._read_status()
  File "C:\Users\waard\anaconda3\lib\http\client.py", line 277, in _read_status
    line = str(self.fp.readline(_MAXLINE + 1), "iso-8859-1")
  File "C:\Users\waard\anaconda3\lib\socket.py", line 669, in readinto
    return self._sock.recv_into(b)
  File "C:\Users\waard\anaconda3\lib\ssl.py", line 1241, in recv_into
    return self.read(nbytes, buffer)
  File "C:\Users\waard\anaconda3\lib\ssl.py", line 1099, in read
    return self._sslobj.read(len, buffer)
socket.timeout: The read operation timed out

During handling of the above exception, another exception occurred:

Traceback (most recent call last):
  File "C:\Users\waard\Desktop\my-app\py\env_v3.8.12\lib\site-packages\requests\adapters.py", line 440, in send
    resp = conn.urlopen(
  File "C:\Users\waard\Desktop\my-app\py\env_v3.8.12\lib\site-packages\urllib3\connectionpool.py", line 785, in urlopen
    retries = retries.increment(
  File "C:\Users\waard\Desktop\my-app\py\env_v3.8.12\lib\site-packages\urllib3\util\retry.py", line 550, in increment
    raise six.reraise(type(error), error, _stacktrace)
  File "C:\Users\waard\Desktop\my-app\py\env_v3.8.12\lib\site-packages\urllib3\packages\six.py", line 770, in reraise
    raise value
  File "C:\Users\waard\Desktop\my-app\py\env_v3.8.12\lib\site-packages\urllib3\connectionpool.py", line 703, in urlopen
    httplib_response = self._make_request(
  File "C:\Users\waard\Desktop\my-app\py\env_v3.8.12\lib\site-packages\urllib3\connectionpool.py", line 451, in _make_request
    self._raise_timeout(err=e, url=url, timeout_value=read_timeout)
  File "C:\Users\waard\Desktop\my-app\py\env_v3.8.12\lib\site-packages\urllib3\connectionpool.py", line 340, in _raise_timeout
    raise ReadTimeoutError(
urllib3.exceptions.ReadTimeoutError: HTTPSConnectionPool(host='zozo.jp', port=443): Read timed out. (read timeout=7.5)

During handling of the above exception, another exception occurred:

Traceback (most recent call last):
  File "./py/connect.py", line 199, in executeGetRequest
    res = requests.get(arrayList['crawlingurl'], timeout=(3.0, 7.5))
  File "C:\Users\waard\Desktop\my-app\py\env_v3.8.12\lib\site-packages\requests\api.py", line 75, in get
    return request('get', url, params=params, **kwargs)
  File "C:\Users\waard\Desktop\my-app\py\env_v3.8.12\lib\site-packages\requests\api.py", line 61, in request
    return session.request(method=method, url=url, **kwargs)
  File "C:\Users\waard\Desktop\my-app\py\env_v3.8.12\lib\site-packages\requests\sessions.py", line 529, in request
    resp = self.send(prep, **send_kwargs)
  File "C:\Users\waard\Desktop\my-app\py\env_v3.8.12\lib\site-packages\requests\sessions.py", line 645, in send
    r = adapter.send(request, **kwargs)
  File "C:\Users\waard\Desktop\my-app\py\env_v3.8.12\lib\site-packages\requests\adapters.py", line 532, in send
    raise ReadTimeout(e, request=request)
requests.exceptions.ReadTimeout: HTTPSConnectionPool(host='zozo.jp', port=443): Read timed out. (read timeout=7.5)

2022-01-25 22:51:40,359 <ERROR> :  occered at executeGetRequest <class 'requests.exceptions.ReadTimeout'>
2022-01-25 22:51:40,359 <ERROR> : Traceback (most recent call last):
  File "C:\Users\waard\Desktop\my-app\py\env_v3.8.12\lib\site-packages\urllib3\connectionpool.py", line 449, in _make_request
    six.raise_from(e, None)
  File "<string>", line 3, in raise_from
  File "C:\Users\waard\Desktop\my-app\py\env_v3.8.12\lib\site-packages\urllib3\connectionpool.py", line 444, in _make_request
    httplib_response = conn.getresponse()
  File "C:\Users\waard\anaconda3\lib\http\client.py", line 1348, in getresponse
    response.begin()
  File "C:\Users\waard\anaconda3\lib\http\client.py", line 316, in begin
    version, status, reason = self._read_status()
  File "C:\Users\waard\anaconda3\lib\http\client.py", line 277, in _read_status
    line = str(self.fp.readline(_MAXLINE + 1), "iso-8859-1")
  File "C:\Users\waard\anaconda3\lib\socket.py", line 669, in readinto
    return self._sock.recv_into(b)
  File "C:\Users\waard\anaconda3\lib\ssl.py", line 1241, in recv_into
    return self.read(nbytes, buffer)
  File "C:\Users\waard\anaconda3\lib\ssl.py", line 1099, in read
    return self._sslobj.read(len, buffer)
socket.timeout: The read operation timed out

During handling of the above exception, another exception occurred:

Traceback (most recent call last):
  File "C:\Users\waard\Desktop\my-app\py\env_v3.8.12\lib\site-packages\requests\adapters.py", line 440, in send
    resp = conn.urlopen(
  File "C:\Users\waard\Desktop\my-app\py\env_v3.8.12\lib\site-packages\urllib3\connectionpool.py", line 785, in urlopen
    retries = retries.increment(
  File "C:\Users\waard\Desktop\my-app\py\env_v3.8.12\lib\site-packages\urllib3\util\retry.py", line 550, in increment
    raise six.reraise(type(error), error, _stacktrace)
  File "C:\Users\waard\Desktop\my-app\py\env_v3.8.12\lib\site-packages\urllib3\packages\six.py", line 770, in reraise
    raise value
  File "C:\Users\waard\Desktop\my-app\py\env_v3.8.12\lib\site-packages\urllib3\connectionpool.py", line 703, in urlopen
    httplib_response = self._make_request(
  File "C:\Users\waard\Desktop\my-app\py\env_v3.8.12\lib\site-packages\urllib3\connectionpool.py", line 451, in _make_request
    self._raise_timeout(err=e, url=url, timeout_value=read_timeout)
  File "C:\Users\waard\Desktop\my-app\py\env_v3.8.12\lib\site-packages\urllib3\connectionpool.py", line 340, in _raise_timeout
    raise ReadTimeoutError(
urllib3.exceptions.ReadTimeoutError: HTTPSConnectionPool(host='zozo.jp', port=443): Read timed out. (read timeout=7.5)

During handling of the above exception, another exception occurred:

Traceback (most recent call last):
  File "./py/connect.py", line 199, in executeGetRequest
    res = requests.get(arrayList['crawlingurl'], timeout=(3.0, 7.5))
  File "C:\Users\waard\Desktop\my-app\py\env_v3.8.12\lib\site-packages\requests\api.py", line 75, in get
    return request('get', url, params=params, **kwargs)
  File "C:\Users\waard\Desktop\my-app\py\env_v3.8.12\lib\site-packages\requests\api.py", line 61, in request
    return session.request(method=method, url=url, **kwargs)
  File "C:\Users\waard\Desktop\my-app\py\env_v3.8.12\lib\site-packages\requests\sessions.py", line 529, in request
    resp = self.send(prep, **send_kwargs)
  File "C:\Users\waard\Desktop\my-app\py\env_v3.8.12\lib\site-packages\requests\sessions.py", line 645, in send
    r = adapter.send(request, **kwargs)
  File "C:\Users\waard\Desktop\my-app\py\env_v3.8.12\lib\site-packages\requests\adapters.py", line 532, in send
    raise ReadTimeout(e, request=request)
requests.exceptions.ReadTimeout: HTTPSConnectionPool(host='zozo.jp', port=443): Read timed out. (read timeout=7.5)

2022-01-25 22:51:47,919 <ERROR> :  occered at executeGetRequest <class 'requests.exceptions.ReadTimeout'>
2022-01-25 22:51:47,919 <ERROR> : Traceback (most recent call last):
  File "C:\Users\waard\Desktop\my-app\py\env_v3.8.12\lib\site-packages\urllib3\connectionpool.py", line 449, in _make_request
    six.raise_from(e, None)
  File "<string>", line 3, in raise_from
  File "C:\Users\waard\Desktop\my-app\py\env_v3.8.12\lib\site-packages\urllib3\connectionpool.py", line 444, in _make_request
    httplib_response = conn.getresponse()
  File "C:\Users\waard\anaconda3\lib\http\client.py", line 1348, in getresponse
    response.begin()
  File "C:\Users\waard\anaconda3\lib\http\client.py", line 316, in begin
    version, status, reason = self._read_status()
  File "C:\Users\waard\anaconda3\lib\http\client.py", line 277, in _read_status
    line = str(self.fp.readline(_MAXLINE + 1), "iso-8859-1")
  File "C:\Users\waard\anaconda3\lib\socket.py", line 669, in readinto
    return self._sock.recv_into(b)
  File "C:\Users\waard\anaconda3\lib\ssl.py", line 1241, in recv_into
    return self.read(nbytes, buffer)
  File "C:\Users\waard\anaconda3\lib\ssl.py", line 1099, in read
    return self._sslobj.read(len, buffer)
socket.timeout: The read operation timed out

During handling of the above exception, another exception occurred:

Traceback (most recent call last):
  File "C:\Users\waard\Desktop\my-app\py\env_v3.8.12\lib\site-packages\requests\adapters.py", line 440, in send
    resp = conn.urlopen(
  File "C:\Users\waard\Desktop\my-app\py\env_v3.8.12\lib\site-packages\urllib3\connectionpool.py", line 785, in urlopen
    retries = retries.increment(
  File "C:\Users\waard\Desktop\my-app\py\env_v3.8.12\lib\site-packages\urllib3\util\retry.py", line 550, in increment
    raise six.reraise(type(error), error, _stacktrace)
  File "C:\Users\waard\Desktop\my-app\py\env_v3.8.12\lib\site-packages\urllib3\packages\six.py", line 770, in reraise
    raise value
  File "C:\Users\waard\Desktop\my-app\py\env_v3.8.12\lib\site-packages\urllib3\connectionpool.py", line 703, in urlopen
    httplib_response = self._make_request(
  File "C:\Users\waard\Desktop\my-app\py\env_v3.8.12\lib\site-packages\urllib3\connectionpool.py", line 451, in _make_request
    self._raise_timeout(err=e, url=url, timeout_value=read_timeout)
  File "C:\Users\waard\Desktop\my-app\py\env_v3.8.12\lib\site-packages\urllib3\connectionpool.py", line 340, in _raise_timeout
    raise ReadTimeoutError(
urllib3.exceptions.ReadTimeoutError: HTTPSConnectionPool(host='zozo.jp', port=443): Read timed out. (read timeout=7.5)

During handling of the above exception, another exception occurred:

Traceback (most recent call last):
  File "./py/connect.py", line 199, in executeGetRequest
    res = requests.get(arrayList['crawlingurl'], timeout=(3.0, 7.5))
  File "C:\Users\waard\Desktop\my-app\py\env_v3.8.12\lib\site-packages\requests\api.py", line 75, in get
    return request('get', url, params=params, **kwargs)
  File "C:\Users\waard\Desktop\my-app\py\env_v3.8.12\lib\site-packages\requests\api.py", line 61, in request
    return session.request(method=method, url=url, **kwargs)
  File "C:\Users\waard\Desktop\my-app\py\env_v3.8.12\lib\site-packages\requests\sessions.py", line 529, in request
    resp = self.send(prep, **send_kwargs)
  File "C:\Users\waard\Desktop\my-app\py\env_v3.8.12\lib\site-packages\requests\sessions.py", line 645, in send
    r = adapter.send(request, **kwargs)
  File "C:\Users\waard\Desktop\my-app\py\env_v3.8.12\lib\site-packages\requests\adapters.py", line 532, in send
    raise ReadTimeout(e, request=request)
requests.exceptions.ReadTimeout: HTTPSConnectionPool(host='zozo.jp', port=443): Read timed out. (read timeout=7.5)

2022-01-25 22:51:47,919 <ERROR> :  occered at executeGetRequest Max retries exceeded with urlhttps://zozo.jp/brand/nike/shoes/sneakers/
2022-01-25 22:51:48,875 <ERROR> :  occered at executeGetRequest requests failed:https://www.jiji.com/jc/c?g=pol
2022-01-25 22:51:52,340 <ERROR> :  occered at executeGetRequest requests failed:https://www.jiji.com/jc/c?g=pol
2022-01-25 22:51:55,941 <ERROR> :  occered at executeGetRequest requests failed:https://www.jiji.com/jc/c?g=pol
2022-01-25 22:51:58,947 <ERROR> :  occered at executeGetRequest Max retries exceeded with urlhttps://www.jiji.com/jc/c?g=pol
2022-01-25 23:02:49,486 <ERROR> :  occered at executeGetRequest <class 'ValueError'>1
2022-01-25 23:02:49,486 <ERROR> : Traceback (most recent call last):
  File "./py/connect.py", line 212, in executeGetRequest
    root = lxml.html.fromstring(html)
  File "C:\Users\waard\Desktop\my-app\py\env_v3.8.12\lib\site-packages\lxml\html\__init__.py", line 875, in fromstring
    doc = document_fromstring(html, parser=parser, base_url=base_url, **kw)
  File "C:\Users\waard\Desktop\my-app\py\env_v3.8.12\lib\site-packages\lxml\html\__init__.py", line 761, in document_fromstring
    value = etree.fromstring(html, parser, **kw)
  File "src\lxml\etree.pyx", line 3252, in lxml.etree.fromstring
  File "src\lxml\parser.pxi", line 1907, in lxml.etree._parseMemoryDocument
ValueError: Unicode strings with encoding declaration are not supported. Please use bytes input or XML fragments without declaration.

2022-01-25 23:03:38,905 <ERROR> :  occered at executeGetRequest <class 'requests.exceptions.ReadTimeout'>
2022-01-25 23:03:38,905 <ERROR> : Traceback (most recent call last):
  File "C:\Users\waard\Desktop\my-app\py\env_v3.8.12\lib\site-packages\urllib3\connectionpool.py", line 449, in _make_request
    six.raise_from(e, None)
  File "<string>", line 3, in raise_from
  File "C:\Users\waard\Desktop\my-app\py\env_v3.8.12\lib\site-packages\urllib3\connectionpool.py", line 444, in _make_request
    httplib_response = conn.getresponse()
  File "C:\Users\waard\anaconda3\lib\http\client.py", line 1348, in getresponse
    response.begin()
  File "C:\Users\waard\anaconda3\lib\http\client.py", line 316, in begin
    version, status, reason = self._read_status()
  File "C:\Users\waard\anaconda3\lib\http\client.py", line 277, in _read_status
    line = str(self.fp.readline(_MAXLINE + 1), "iso-8859-1")
  File "C:\Users\waard\anaconda3\lib\socket.py", line 669, in readinto
    return self._sock.recv_into(b)
  File "C:\Users\waard\anaconda3\lib\ssl.py", line 1241, in recv_into
    return self.read(nbytes, buffer)
  File "C:\Users\waard\anaconda3\lib\ssl.py", line 1099, in read
    return self._sslobj.read(len, buffer)
socket.timeout: The read operation timed out

During handling of the above exception, another exception occurred:

Traceback (most recent call last):
  File "C:\Users\waard\Desktop\my-app\py\env_v3.8.12\lib\site-packages\requests\adapters.py", line 440, in send
    resp = conn.urlopen(
  File "C:\Users\waard\Desktop\my-app\py\env_v3.8.12\lib\site-packages\urllib3\connectionpool.py", line 785, in urlopen
    retries = retries.increment(
  File "C:\Users\waard\Desktop\my-app\py\env_v3.8.12\lib\site-packages\urllib3\util\retry.py", line 550, in increment
    raise six.reraise(type(error), error, _stacktrace)
  File "C:\Users\waard\Desktop\my-app\py\env_v3.8.12\lib\site-packages\urllib3\packages\six.py", line 770, in reraise
    raise value
  File "C:\Users\waard\Desktop\my-app\py\env_v3.8.12\lib\site-packages\urllib3\connectionpool.py", line 703, in urlopen
    httplib_response = self._make_request(
  File "C:\Users\waard\Desktop\my-app\py\env_v3.8.12\lib\site-packages\urllib3\connectionpool.py", line 451, in _make_request
    self._raise_timeout(err=e, url=url, timeout_value=read_timeout)
  File "C:\Users\waard\Desktop\my-app\py\env_v3.8.12\lib\site-packages\urllib3\connectionpool.py", line 340, in _raise_timeout
    raise ReadTimeoutError(
urllib3.exceptions.ReadTimeoutError: HTTPSConnectionPool(host='zozo.jp', port=443): Read timed out. (read timeout=7.5)

During handling of the above exception, another exception occurred:

Traceback (most recent call last):
  File "./py/connect.py", line 201, in executeGetRequest
    res = requests.get(arrayList['crawlingurl'], timeout=(3.0, 7.5))
  File "C:\Users\waard\Desktop\my-app\py\env_v3.8.12\lib\site-packages\requests\api.py", line 75, in get
    return request('get', url, params=params, **kwargs)
  File "C:\Users\waard\Desktop\my-app\py\env_v3.8.12\lib\site-packages\requests\api.py", line 61, in request
    return session.request(method=method, url=url, **kwargs)
  File "C:\Users\waard\Desktop\my-app\py\env_v3.8.12\lib\site-packages\requests\sessions.py", line 529, in request
    resp = self.send(prep, **send_kwargs)
  File "C:\Users\waard\Desktop\my-app\py\env_v3.8.12\lib\site-packages\requests\sessions.py", line 645, in send
    r = adapter.send(request, **kwargs)
  File "C:\Users\waard\Desktop\my-app\py\env_v3.8.12\lib\site-packages\requests\adapters.py", line 532, in send
    raise ReadTimeout(e, request=request)
requests.exceptions.ReadTimeout: HTTPSConnectionPool(host='zozo.jp', port=443): Read timed out. (read timeout=7.5)

2022-01-25 23:03:46,482 <ERROR> :  occered at executeGetRequest <class 'requests.exceptions.ReadTimeout'>
2022-01-25 23:03:46,483 <ERROR> : Traceback (most recent call last):
  File "C:\Users\waard\Desktop\my-app\py\env_v3.8.12\lib\site-packages\urllib3\connectionpool.py", line 449, in _make_request
    six.raise_from(e, None)
  File "<string>", line 3, in raise_from
  File "C:\Users\waard\Desktop\my-app\py\env_v3.8.12\lib\site-packages\urllib3\connectionpool.py", line 444, in _make_request
    httplib_response = conn.getresponse()
  File "C:\Users\waard\anaconda3\lib\http\client.py", line 1348, in getresponse
    response.begin()
  File "C:\Users\waard\anaconda3\lib\http\client.py", line 316, in begin
    version, status, reason = self._read_status()
  File "C:\Users\waard\anaconda3\lib\http\client.py", line 277, in _read_status
    line = str(self.fp.readline(_MAXLINE + 1), "iso-8859-1")
  File "C:\Users\waard\anaconda3\lib\socket.py", line 669, in readinto
    return self._sock.recv_into(b)
  File "C:\Users\waard\anaconda3\lib\ssl.py", line 1241, in recv_into
    return self.read(nbytes, buffer)
  File "C:\Users\waard\anaconda3\lib\ssl.py", line 1099, in read
    return self._sslobj.read(len, buffer)
socket.timeout: The read operation timed out

During handling of the above exception, another exception occurred:

Traceback (most recent call last):
  File "C:\Users\waard\Desktop\my-app\py\env_v3.8.12\lib\site-packages\requests\adapters.py", line 440, in send
    resp = conn.urlopen(
  File "C:\Users\waard\Desktop\my-app\py\env_v3.8.12\lib\site-packages\urllib3\connectionpool.py", line 785, in urlopen
    retries = retries.increment(
  File "C:\Users\waard\Desktop\my-app\py\env_v3.8.12\lib\site-packages\urllib3\util\retry.py", line 550, in increment
    raise six.reraise(type(error), error, _stacktrace)
  File "C:\Users\waard\Desktop\my-app\py\env_v3.8.12\lib\site-packages\urllib3\packages\six.py", line 770, in reraise
    raise value
  File "C:\Users\waard\Desktop\my-app\py\env_v3.8.12\lib\site-packages\urllib3\connectionpool.py", line 703, in urlopen
    httplib_response = self._make_request(
  File "C:\Users\waard\Desktop\my-app\py\env_v3.8.12\lib\site-packages\urllib3\connectionpool.py", line 451, in _make_request
    self._raise_timeout(err=e, url=url, timeout_value=read_timeout)
  File "C:\Users\waard\Desktop\my-app\py\env_v3.8.12\lib\site-packages\urllib3\connectionpool.py", line 340, in _raise_timeout
    raise ReadTimeoutError(
urllib3.exceptions.ReadTimeoutError: HTTPSConnectionPool(host='zozo.jp', port=443): Read timed out. (read timeout=7.5)

During handling of the above exception, another exception occurred:

Traceback (most recent call last):
  File "./py/connect.py", line 201, in executeGetRequest
    res = requests.get(arrayList['crawlingurl'], timeout=(3.0, 7.5))
  File "C:\Users\waard\Desktop\my-app\py\env_v3.8.12\lib\site-packages\requests\api.py", line 75, in get
    return request('get', url, params=params, **kwargs)
  File "C:\Users\waard\Desktop\my-app\py\env_v3.8.12\lib\site-packages\requests\api.py", line 61, in request
    return session.request(method=method, url=url, **kwargs)
  File "C:\Users\waard\Desktop\my-app\py\env_v3.8.12\lib\site-packages\requests\sessions.py", line 529, in request
    resp = self.send(prep, **send_kwargs)
  File "C:\Users\waard\Desktop\my-app\py\env_v3.8.12\lib\site-packages\requests\sessions.py", line 645, in send
    r = adapter.send(request, **kwargs)
  File "C:\Users\waard\Desktop\my-app\py\env_v3.8.12\lib\site-packages\requests\adapters.py", line 532, in send
    raise ReadTimeout(e, request=request)
requests.exceptions.ReadTimeout: HTTPSConnectionPool(host='zozo.jp', port=443): Read timed out. (read timeout=7.5)

2022-01-25 23:03:54,076 <ERROR> :  occered at executeGetRequest <class 'requests.exceptions.ReadTimeout'>
2022-01-25 23:03:54,076 <ERROR> : Traceback (most recent call last):
  File "C:\Users\waard\Desktop\my-app\py\env_v3.8.12\lib\site-packages\urllib3\connectionpool.py", line 449, in _make_request
    six.raise_from(e, None)
  File "<string>", line 3, in raise_from
  File "C:\Users\waard\Desktop\my-app\py\env_v3.8.12\lib\site-packages\urllib3\connectionpool.py", line 444, in _make_request
    httplib_response = conn.getresponse()
  File "C:\Users\waard\anaconda3\lib\http\client.py", line 1348, in getresponse
    response.begin()
  File "C:\Users\waard\anaconda3\lib\http\client.py", line 316, in begin
    version, status, reason = self._read_status()
  File "C:\Users\waard\anaconda3\lib\http\client.py", line 277, in _read_status
    line = str(self.fp.readline(_MAXLINE + 1), "iso-8859-1")
  File "C:\Users\waard\anaconda3\lib\socket.py", line 669, in readinto
    return self._sock.recv_into(b)
  File "C:\Users\waard\anaconda3\lib\ssl.py", line 1241, in recv_into
    return self.read(nbytes, buffer)
  File "C:\Users\waard\anaconda3\lib\ssl.py", line 1099, in read
    return self._sslobj.read(len, buffer)
socket.timeout: The read operation timed out

During handling of the above exception, another exception occurred:

Traceback (most recent call last):
  File "C:\Users\waard\Desktop\my-app\py\env_v3.8.12\lib\site-packages\requests\adapters.py", line 440, in send
    resp = conn.urlopen(
  File "C:\Users\waard\Desktop\my-app\py\env_v3.8.12\lib\site-packages\urllib3\connectionpool.py", line 785, in urlopen
    retries = retries.increment(
  File "C:\Users\waard\Desktop\my-app\py\env_v3.8.12\lib\site-packages\urllib3\util\retry.py", line 550, in increment
    raise six.reraise(type(error), error, _stacktrace)
  File "C:\Users\waard\Desktop\my-app\py\env_v3.8.12\lib\site-packages\urllib3\packages\six.py", line 770, in reraise
    raise value
  File "C:\Users\waard\Desktop\my-app\py\env_v3.8.12\lib\site-packages\urllib3\connectionpool.py", line 703, in urlopen
    httplib_response = self._make_request(
  File "C:\Users\waard\Desktop\my-app\py\env_v3.8.12\lib\site-packages\urllib3\connectionpool.py", line 451, in _make_request
    self._raise_timeout(err=e, url=url, timeout_value=read_timeout)
  File "C:\Users\waard\Desktop\my-app\py\env_v3.8.12\lib\site-packages\urllib3\connectionpool.py", line 340, in _raise_timeout
    raise ReadTimeoutError(
urllib3.exceptions.ReadTimeoutError: HTTPSConnectionPool(host='zozo.jp', port=443): Read timed out. (read timeout=7.5)

During handling of the above exception, another exception occurred:

Traceback (most recent call last):
  File "./py/connect.py", line 201, in executeGetRequest
    res = requests.get(arrayList['crawlingurl'], timeout=(3.0, 7.5))
  File "C:\Users\waard\Desktop\my-app\py\env_v3.8.12\lib\site-packages\requests\api.py", line 75, in get
    return request('get', url, params=params, **kwargs)
  File "C:\Users\waard\Desktop\my-app\py\env_v3.8.12\lib\site-packages\requests\api.py", line 61, in request
    return session.request(method=method, url=url, **kwargs)
  File "C:\Users\waard\Desktop\my-app\py\env_v3.8.12\lib\site-packages\requests\sessions.py", line 529, in request
    resp = self.send(prep, **send_kwargs)
  File "C:\Users\waard\Desktop\my-app\py\env_v3.8.12\lib\site-packages\requests\sessions.py", line 645, in send
    r = adapter.send(request, **kwargs)
  File "C:\Users\waard\Desktop\my-app\py\env_v3.8.12\lib\site-packages\requests\adapters.py", line 532, in send
    raise ReadTimeout(e, request=request)
requests.exceptions.ReadTimeout: HTTPSConnectionPool(host='zozo.jp', port=443): Read timed out. (read timeout=7.5)

2022-01-25 23:03:54,076 <ERROR> :  occered at executeGetRequest Max retries exceeded with urlhttps://zozo.jp/brand/nike/shoes/sneakers/
2022-01-25 23:03:54,919 <ERROR> :  occered at executeGetRequest requests failed:https://www.jiji.com/jc/c?g=pol
2022-01-25 23:03:58,468 <ERROR> :  occered at executeGetRequest requests failed:https://www.jiji.com/jc/c?g=pol
2022-01-25 23:04:01,989 <ERROR> :  occered at executeGetRequest requests failed:https://www.jiji.com/jc/c?g=pol
2022-01-25 23:04:05,005 <ERROR> :  occered at executeGetRequest Max retries exceeded with urlhttps://www.jiji.com/jc/c?g=pol
