2022-01-14 01:47:02,497 <ERROR> :  occered at executeGetRequest <class 'ValueError'>1
2022-01-14 01:47:02,504 <ERROR> : Traceback (most recent call last):
  File "c:/Users/waard/Desktop/my-app/py/connect.py", line 194, in executeGetRequest
    root = lxml.html.fromstring(html)
  File "C:\Users\waard\anaconda3\lib\site-packages\lxml\html\__init__.py", line 875, in fromstring
    doc = document_fromstring(html, parser=parser, base_url=base_url, **kw)
  File "C:\Users\waard\anaconda3\lib\site-packages\lxml\html\__init__.py", line 761, in document_fromstring
    value = etree.fromstring(html, parser, **kw)
  File "src/lxml/etree.pyx", line 3237, in lxml.etree.fromstring
  File "src/lxml/parser.pxi", line 1891, in lxml.etree._parseMemoryDocument
ValueError: Unicode strings with encoding declaration are not supported. Please use bytes input or XML fragments without declaration.

2022-01-14 01:48:03,820 <ERROR> :  occered at executeGetRequest <class 'requests.exceptions.ReadTimeout'>
2022-01-14 01:48:03,833 <ERROR> : Traceback (most recent call last):
  File "C:\Users\waard\anaconda3\lib\site-packages\urllib3\connectionpool.py", line 445, in _make_request
    six.raise_from(e, None)
  File "<string>", line 3, in raise_from
  File "C:\Users\waard\anaconda3\lib\site-packages\urllib3\connectionpool.py", line 440, in _make_request
    httplib_response = conn.getresponse()
  File "C:\Users\waard\anaconda3\lib\http\client.py", line 1344, in getresponse
    response.begin()
  File "C:\Users\waard\anaconda3\lib\http\client.py", line 307, in begin
    version, status, reason = self._read_status()
  File "C:\Users\waard\anaconda3\lib\http\client.py", line 268, in _read_status
    line = str(self.fp.readline(_MAXLINE + 1), "iso-8859-1")
  File "C:\Users\waard\anaconda3\lib\socket.py", line 669, in readinto
    return self._sock.recv_into(b)
  File "C:\Users\waard\anaconda3\lib\ssl.py", line 1241, in recv_into
    return self.read(nbytes, buffer)
  File "C:\Users\waard\anaconda3\lib\ssl.py", line 1099, in read
    return self._sslobj.read(len, buffer)
socket.timeout: The read operation timed out

During handling of the above exception, another exception occurred:

Traceback (most recent call last):
  File "C:\Users\waard\anaconda3\lib\site-packages\requests\adapters.py", line 439, in send
    resp = conn.urlopen(
  File "C:\Users\waard\anaconda3\lib\site-packages\urllib3\connectionpool.py", line 755, in urlopen
    retries = retries.increment(
  File "C:\Users\waard\anaconda3\lib\site-packages\urllib3\util\retry.py", line 532, in increment
    raise six.reraise(type(error), error, _stacktrace)
  File "C:\Users\waard\anaconda3\lib\site-packages\urllib3\packages\six.py", line 770, in reraise
    raise value
  File "C:\Users\waard\anaconda3\lib\site-packages\urllib3\connectionpool.py", line 699, in urlopen
    httplib_response = self._make_request(
  File "C:\Users\waard\anaconda3\lib\site-packages\urllib3\connectionpool.py", line 447, in _make_request
    self._raise_timeout(err=e, url=url, timeout_value=read_timeout)
  File "C:\Users\waard\anaconda3\lib\site-packages\urllib3\connectionpool.py", line 336, in _raise_timeout
    raise ReadTimeoutError(
urllib3.exceptions.ReadTimeoutError: HTTPSConnectionPool(host='zozo.jp', port=443): Read timed out. (read timeout=7.5)

During handling of the above exception, another exception occurred:

Traceback (most recent call last):
  File "c:/Users/waard/Desktop/my-app/py/connect.py", line 186, in executeGetRequest
    res = requests.get(arrayList['crawlingurl'], timeout=(3.0, 7.5))
  File "C:\Users\waard\anaconda3\lib\site-packages\requests\api.py", line 76, in get
    return request('get', url, params=params, **kwargs)
  File "C:\Users\waard\anaconda3\lib\site-packages\requests\api.py", line 61, in request
    return session.request(method=method, url=url, **kwargs)
  File "C:\Users\waard\anaconda3\lib\site-packages\requests\sessions.py", line 542, in request
    resp = self.send(prep, **send_kwargs)
  File "C:\Users\waard\anaconda3\lib\site-packages\requests\sessions.py", line 655, in send
    r = adapter.send(request, **kwargs)
  File "C:\Users\waard\anaconda3\lib\site-packages\requests\adapters.py", line 529, in send
    raise ReadTimeout(e, request=request)
requests.exceptions.ReadTimeout: HTTPSConnectionPool(host='zozo.jp', port=443): Read timed out. (read timeout=7.5)

2022-01-14 01:48:11,408 <ERROR> :  occered at executeGetRequest <class 'requests.exceptions.ReadTimeout'>
2022-01-14 01:48:11,414 <ERROR> : Traceback (most recent call last):
  File "C:\Users\waard\anaconda3\lib\site-packages\urllib3\connectionpool.py", line 445, in _make_request
    six.raise_from(e, None)
  File "<string>", line 3, in raise_from
  File "C:\Users\waard\anaconda3\lib\site-packages\urllib3\connectionpool.py", line 440, in _make_request
    httplib_response = conn.getresponse()
  File "C:\Users\waard\anaconda3\lib\http\client.py", line 1344, in getresponse
    response.begin()
  File "C:\Users\waard\anaconda3\lib\http\client.py", line 307, in begin
    version, status, reason = self._read_status()
  File "C:\Users\waard\anaconda3\lib\http\client.py", line 268, in _read_status
    line = str(self.fp.readline(_MAXLINE + 1), "iso-8859-1")
  File "C:\Users\waard\anaconda3\lib\socket.py", line 669, in readinto
    return self._sock.recv_into(b)
  File "C:\Users\waard\anaconda3\lib\ssl.py", line 1241, in recv_into
    return self.read(nbytes, buffer)
  File "C:\Users\waard\anaconda3\lib\ssl.py", line 1099, in read
    return self._sslobj.read(len, buffer)
socket.timeout: The read operation timed out

During handling of the above exception, another exception occurred:

Traceback (most recent call last):
  File "C:\Users\waard\anaconda3\lib\site-packages\requests\adapters.py", line 439, in send
    resp = conn.urlopen(
  File "C:\Users\waard\anaconda3\lib\site-packages\urllib3\connectionpool.py", line 755, in urlopen
    retries = retries.increment(
  File "C:\Users\waard\anaconda3\lib\site-packages\urllib3\util\retry.py", line 532, in increment
    raise six.reraise(type(error), error, _stacktrace)
  File "C:\Users\waard\anaconda3\lib\site-packages\urllib3\packages\six.py", line 770, in reraise
    raise value
  File "C:\Users\waard\anaconda3\lib\site-packages\urllib3\connectionpool.py", line 699, in urlopen
    httplib_response = self._make_request(
  File "C:\Users\waard\anaconda3\lib\site-packages\urllib3\connectionpool.py", line 447, in _make_request
    self._raise_timeout(err=e, url=url, timeout_value=read_timeout)
  File "C:\Users\waard\anaconda3\lib\site-packages\urllib3\connectionpool.py", line 336, in _raise_timeout
    raise ReadTimeoutError(
urllib3.exceptions.ReadTimeoutError: HTTPSConnectionPool(host='zozo.jp', port=443): Read timed out. (read timeout=7.5)

During handling of the above exception, another exception occurred:

Traceback (most recent call last):
  File "c:/Users/waard/Desktop/my-app/py/connect.py", line 186, in executeGetRequest
    res = requests.get(arrayList['crawlingurl'], timeout=(3.0, 7.5))
  File "C:\Users\waard\anaconda3\lib\site-packages\requests\api.py", line 76, in get
    return request('get', url, params=params, **kwargs)
  File "C:\Users\waard\anaconda3\lib\site-packages\requests\api.py", line 61, in request
    return session.request(method=method, url=url, **kwargs)
  File "C:\Users\waard\anaconda3\lib\site-packages\requests\sessions.py", line 542, in request
    resp = self.send(prep, **send_kwargs)
  File "C:\Users\waard\anaconda3\lib\site-packages\requests\sessions.py", line 655, in send
    r = adapter.send(request, **kwargs)
  File "C:\Users\waard\anaconda3\lib\site-packages\requests\adapters.py", line 529, in send
    raise ReadTimeout(e, request=request)
requests.exceptions.ReadTimeout: HTTPSConnectionPool(host='zozo.jp', port=443): Read timed out. (read timeout=7.5)

2022-01-14 01:48:18,988 <ERROR> :  occered at executeGetRequest <class 'requests.exceptions.ReadTimeout'>
2022-01-14 01:48:18,990 <ERROR> : Traceback (most recent call last):
  File "C:\Users\waard\anaconda3\lib\site-packages\urllib3\connectionpool.py", line 445, in _make_request
    six.raise_from(e, None)
  File "<string>", line 3, in raise_from
  File "C:\Users\waard\anaconda3\lib\site-packages\urllib3\connectionpool.py", line 440, in _make_request
    httplib_response = conn.getresponse()
  File "C:\Users\waard\anaconda3\lib\http\client.py", line 1344, in getresponse
    response.begin()
  File "C:\Users\waard\anaconda3\lib\http\client.py", line 307, in begin
    version, status, reason = self._read_status()
  File "C:\Users\waard\anaconda3\lib\http\client.py", line 268, in _read_status
    line = str(self.fp.readline(_MAXLINE + 1), "iso-8859-1")
  File "C:\Users\waard\anaconda3\lib\socket.py", line 669, in readinto
    return self._sock.recv_into(b)
  File "C:\Users\waard\anaconda3\lib\ssl.py", line 1241, in recv_into
    return self.read(nbytes, buffer)
  File "C:\Users\waard\anaconda3\lib\ssl.py", line 1099, in read
    return self._sslobj.read(len, buffer)
socket.timeout: The read operation timed out

During handling of the above exception, another exception occurred:

Traceback (most recent call last):
  File "C:\Users\waard\anaconda3\lib\site-packages\requests\adapters.py", line 439, in send
    resp = conn.urlopen(
  File "C:\Users\waard\anaconda3\lib\site-packages\urllib3\connectionpool.py", line 755, in urlopen
    retries = retries.increment(
  File "C:\Users\waard\anaconda3\lib\site-packages\urllib3\util\retry.py", line 532, in increment
    raise six.reraise(type(error), error, _stacktrace)
  File "C:\Users\waard\anaconda3\lib\site-packages\urllib3\packages\six.py", line 770, in reraise
    raise value
  File "C:\Users\waard\anaconda3\lib\site-packages\urllib3\connectionpool.py", line 699, in urlopen
    httplib_response = self._make_request(
  File "C:\Users\waard\anaconda3\lib\site-packages\urllib3\connectionpool.py", line 447, in _make_request
    self._raise_timeout(err=e, url=url, timeout_value=read_timeout)
  File "C:\Users\waard\anaconda3\lib\site-packages\urllib3\connectionpool.py", line 336, in _raise_timeout
    raise ReadTimeoutError(
urllib3.exceptions.ReadTimeoutError: HTTPSConnectionPool(host='zozo.jp', port=443): Read timed out. (read timeout=7.5)

During handling of the above exception, another exception occurred:

Traceback (most recent call last):
  File "c:/Users/waard/Desktop/my-app/py/connect.py", line 186, in executeGetRequest
    res = requests.get(arrayList['crawlingurl'], timeout=(3.0, 7.5))
  File "C:\Users\waard\anaconda3\lib\site-packages\requests\api.py", line 76, in get
    return request('get', url, params=params, **kwargs)
  File "C:\Users\waard\anaconda3\lib\site-packages\requests\api.py", line 61, in request
    return session.request(method=method, url=url, **kwargs)
  File "C:\Users\waard\anaconda3\lib\site-packages\requests\sessions.py", line 542, in request
    resp = self.send(prep, **send_kwargs)
  File "C:\Users\waard\anaconda3\lib\site-packages\requests\sessions.py", line 655, in send
    r = adapter.send(request, **kwargs)
  File "C:\Users\waard\anaconda3\lib\site-packages\requests\adapters.py", line 529, in send
    raise ReadTimeout(e, request=request)
requests.exceptions.ReadTimeout: HTTPSConnectionPool(host='zozo.jp', port=443): Read timed out. (read timeout=7.5)

2022-01-14 01:48:19,001 <ERROR> :  occered at executeGetRequest Max retries exceeded with urlhttps://zozo.jp/brand/nike/shoes/sneakers/
2022-01-14 01:48:19,773 <ERROR> :  occered at executeGetRequest requests failed:https://www.jiji.com/jc/c?g=pol
2022-01-14 01:48:23,345 <ERROR> :  occered at executeGetRequest requests failed:https://www.jiji.com/jc/c?g=pol
2022-01-14 01:48:26,969 <ERROR> :  occered at executeGetRequest requests failed:https://www.jiji.com/jc/c?g=pol
2022-01-14 01:48:29,971 <ERROR> :  occered at executeGetRequest Max retries exceeded with urlhttps://www.jiji.com/jc/c?g=pol
2022-01-14 01:54:20,815 <ERROR> :  occered at executeGetRequest <class 'ValueError'>1
2022-01-14 01:54:20,817 <ERROR> : Traceback (most recent call last):
  File "c:/Users/waard/Desktop/my-app/py/connect.py", line 194, in executeGetRequest
    root = lxml.html.fromstring(html)
  File "C:\Users\waard\Desktop\my-app\py\env_v3.8.12\lib\site-packages\lxml\html\__init__.py", line 875, in fromstring
    doc = document_fromstring(html, parser=parser, base_url=base_url, **kw)
  File "C:\Users\waard\Desktop\my-app\py\env_v3.8.12\lib\site-packages\lxml\html\__init__.py", line 761, in document_fromstring
    value = etree.fromstring(html, parser, **kw)
  File "src\lxml\etree.pyx", line 3252, in lxml.etree.fromstring
  File "src\lxml\parser.pxi", line 1907, in lxml.etree._parseMemoryDocument
ValueError: Unicode strings with encoding declaration are not supported. Please use bytes input or XML fragments without declaration.

2022-01-14 01:55:13,044 <ERROR> :  occered at executeGetRequest <class 'requests.exceptions.ReadTimeout'>
2022-01-14 01:55:13,044 <ERROR> : Traceback (most recent call last):
  File "C:\Users\waard\Desktop\my-app\py\env_v3.8.12\lib\site-packages\urllib3\connectionpool.py", line 449, in _make_request
    six.raise_from(e, None)
  File "<string>", line 3, in raise_from
  File "C:\Users\waard\Desktop\my-app\py\env_v3.8.12\lib\site-packages\urllib3\connectionpool.py", line 444, in _make_request
    httplib_response = conn.getresponse()
  File "C:\Users\waard\anaconda3\lib\http\client.py", line 1344, in getresponse
    response.begin()
  File "C:\Users\waard\anaconda3\lib\http\client.py", line 307, in begin
    version, status, reason = self._read_status()
  File "C:\Users\waard\anaconda3\lib\http\client.py", line 268, in _read_status
    line = str(self.fp.readline(_MAXLINE + 1), "iso-8859-1")
  File "C:\Users\waard\anaconda3\lib\socket.py", line 669, in readinto
    return self._sock.recv_into(b)
  File "C:\Users\waard\anaconda3\lib\ssl.py", line 1241, in recv_into
    return self.read(nbytes, buffer)
  File "C:\Users\waard\anaconda3\lib\ssl.py", line 1099, in read
    return self._sslobj.read(len, buffer)
socket.timeout: The read operation timed out

During handling of the above exception, another exception occurred:

Traceback (most recent call last):
  File "C:\Users\waard\Desktop\my-app\py\env_v3.8.12\lib\site-packages\requests\adapters.py", line 440, in send
    resp = conn.urlopen(
  File "C:\Users\waard\Desktop\my-app\py\env_v3.8.12\lib\site-packages\urllib3\connectionpool.py", line 785, in urlopen
    retries = retries.increment(
  File "C:\Users\waard\Desktop\my-app\py\env_v3.8.12\lib\site-packages\urllib3\util\retry.py", line 550, in increment
    raise six.reraise(type(error), error, _stacktrace)
  File "C:\Users\waard\Desktop\my-app\py\env_v3.8.12\lib\site-packages\urllib3\packages\six.py", line 770, in reraise
    raise value
  File "C:\Users\waard\Desktop\my-app\py\env_v3.8.12\lib\site-packages\urllib3\connectionpool.py", line 703, in urlopen
    httplib_response = self._make_request(
  File "C:\Users\waard\Desktop\my-app\py\env_v3.8.12\lib\site-packages\urllib3\connectionpool.py", line 451, in _make_request
    self._raise_timeout(err=e, url=url, timeout_value=read_timeout)
  File "C:\Users\waard\Desktop\my-app\py\env_v3.8.12\lib\site-packages\urllib3\connectionpool.py", line 340, in _raise_timeout
    raise ReadTimeoutError(
urllib3.exceptions.ReadTimeoutError: HTTPSConnectionPool(host='zozo.jp', port=443): Read timed out. (read timeout=7.5)

During handling of the above exception, another exception occurred:

Traceback (most recent call last):
  File "c:/Users/waard/Desktop/my-app/py/connect.py", line 186, in executeGetRequest
    res = requests.get(arrayList['crawlingurl'], timeout=(3.0, 7.5))
  File "C:\Users\waard\Desktop\my-app\py\env_v3.8.12\lib\site-packages\requests\api.py", line 75, in get
    return request('get', url, params=params, **kwargs)
  File "C:\Users\waard\Desktop\my-app\py\env_v3.8.12\lib\site-packages\requests\api.py", line 61, in request
    return session.request(method=method, url=url, **kwargs)
  File "C:\Users\waard\Desktop\my-app\py\env_v3.8.12\lib\site-packages\requests\sessions.py", line 529, in request
    resp = self.send(prep, **send_kwargs)
  File "C:\Users\waard\Desktop\my-app\py\env_v3.8.12\lib\site-packages\requests\sessions.py", line 645, in send
    r = adapter.send(request, **kwargs)
  File "C:\Users\waard\Desktop\my-app\py\env_v3.8.12\lib\site-packages\requests\adapters.py", line 532, in send
    raise ReadTimeout(e, request=request)
requests.exceptions.ReadTimeout: HTTPSConnectionPool(host='zozo.jp', port=443): Read timed out. (read timeout=7.5)

2022-01-14 01:55:20,632 <ERROR> :  occered at executeGetRequest <class 'requests.exceptions.ReadTimeout'>
2022-01-14 01:55:20,632 <ERROR> : Traceback (most recent call last):
  File "C:\Users\waard\Desktop\my-app\py\env_v3.8.12\lib\site-packages\urllib3\connectionpool.py", line 449, in _make_request
    six.raise_from(e, None)
  File "<string>", line 3, in raise_from
  File "C:\Users\waard\Desktop\my-app\py\env_v3.8.12\lib\site-packages\urllib3\connectionpool.py", line 444, in _make_request
    httplib_response = conn.getresponse()
  File "C:\Users\waard\anaconda3\lib\http\client.py", line 1344, in getresponse
    response.begin()
  File "C:\Users\waard\anaconda3\lib\http\client.py", line 307, in begin
    version, status, reason = self._read_status()
  File "C:\Users\waard\anaconda3\lib\http\client.py", line 268, in _read_status
    line = str(self.fp.readline(_MAXLINE + 1), "iso-8859-1")
  File "C:\Users\waard\anaconda3\lib\socket.py", line 669, in readinto
    return self._sock.recv_into(b)
  File "C:\Users\waard\anaconda3\lib\ssl.py", line 1241, in recv_into
    return self.read(nbytes, buffer)
  File "C:\Users\waard\anaconda3\lib\ssl.py", line 1099, in read
    return self._sslobj.read(len, buffer)
socket.timeout: The read operation timed out

During handling of the above exception, another exception occurred:

Traceback (most recent call last):
  File "C:\Users\waard\Desktop\my-app\py\env_v3.8.12\lib\site-packages\requests\adapters.py", line 440, in send
    resp = conn.urlopen(
  File "C:\Users\waard\Desktop\my-app\py\env_v3.8.12\lib\site-packages\urllib3\connectionpool.py", line 785, in urlopen
    retries = retries.increment(
  File "C:\Users\waard\Desktop\my-app\py\env_v3.8.12\lib\site-packages\urllib3\util\retry.py", line 550, in increment
    raise six.reraise(type(error), error, _stacktrace)
  File "C:\Users\waard\Desktop\my-app\py\env_v3.8.12\lib\site-packages\urllib3\packages\six.py", line 770, in reraise
    raise value
  File "C:\Users\waard\Desktop\my-app\py\env_v3.8.12\lib\site-packages\urllib3\connectionpool.py", line 703, in urlopen
    httplib_response = self._make_request(
  File "C:\Users\waard\Desktop\my-app\py\env_v3.8.12\lib\site-packages\urllib3\connectionpool.py", line 451, in _make_request
    self._raise_timeout(err=e, url=url, timeout_value=read_timeout)
  File "C:\Users\waard\Desktop\my-app\py\env_v3.8.12\lib\site-packages\urllib3\connectionpool.py", line 340, in _raise_timeout
    raise ReadTimeoutError(
urllib3.exceptions.ReadTimeoutError: HTTPSConnectionPool(host='zozo.jp', port=443): Read timed out. (read timeout=7.5)

During handling of the above exception, another exception occurred:

Traceback (most recent call last):
  File "c:/Users/waard/Desktop/my-app/py/connect.py", line 186, in executeGetRequest
    res = requests.get(arrayList['crawlingurl'], timeout=(3.0, 7.5))
  File "C:\Users\waard\Desktop\my-app\py\env_v3.8.12\lib\site-packages\requests\api.py", line 75, in get
    return request('get', url, params=params, **kwargs)
  File "C:\Users\waard\Desktop\my-app\py\env_v3.8.12\lib\site-packages\requests\api.py", line 61, in request
    return session.request(method=method, url=url, **kwargs)
  File "C:\Users\waard\Desktop\my-app\py\env_v3.8.12\lib\site-packages\requests\sessions.py", line 529, in request
    resp = self.send(prep, **send_kwargs)
  File "C:\Users\waard\Desktop\my-app\py\env_v3.8.12\lib\site-packages\requests\sessions.py", line 645, in send
    r = adapter.send(request, **kwargs)
  File "C:\Users\waard\Desktop\my-app\py\env_v3.8.12\lib\site-packages\requests\adapters.py", line 532, in send
    raise ReadTimeout(e, request=request)
requests.exceptions.ReadTimeout: HTTPSConnectionPool(host='zozo.jp', port=443): Read timed out. (read timeout=7.5)

2022-01-14 01:55:28,211 <ERROR> :  occered at executeGetRequest <class 'requests.exceptions.ReadTimeout'>
2022-01-14 01:55:28,211 <ERROR> : Traceback (most recent call last):
  File "C:\Users\waard\Desktop\my-app\py\env_v3.8.12\lib\site-packages\urllib3\connectionpool.py", line 449, in _make_request
    six.raise_from(e, None)
  File "<string>", line 3, in raise_from
  File "C:\Users\waard\Desktop\my-app\py\env_v3.8.12\lib\site-packages\urllib3\connectionpool.py", line 444, in _make_request
    httplib_response = conn.getresponse()
  File "C:\Users\waard\anaconda3\lib\http\client.py", line 1344, in getresponse
    response.begin()
  File "C:\Users\waard\anaconda3\lib\http\client.py", line 307, in begin
    version, status, reason = self._read_status()
  File "C:\Users\waard\anaconda3\lib\http\client.py", line 268, in _read_status
    line = str(self.fp.readline(_MAXLINE + 1), "iso-8859-1")
  File "C:\Users\waard\anaconda3\lib\socket.py", line 669, in readinto
    return self._sock.recv_into(b)
  File "C:\Users\waard\anaconda3\lib\ssl.py", line 1241, in recv_into
    return self.read(nbytes, buffer)
  File "C:\Users\waard\anaconda3\lib\ssl.py", line 1099, in read
    return self._sslobj.read(len, buffer)
socket.timeout: The read operation timed out

During handling of the above exception, another exception occurred:

Traceback (most recent call last):
  File "C:\Users\waard\Desktop\my-app\py\env_v3.8.12\lib\site-packages\requests\adapters.py", line 440, in send
    resp = conn.urlopen(
  File "C:\Users\waard\Desktop\my-app\py\env_v3.8.12\lib\site-packages\urllib3\connectionpool.py", line 785, in urlopen
    retries = retries.increment(
  File "C:\Users\waard\Desktop\my-app\py\env_v3.8.12\lib\site-packages\urllib3\util\retry.py", line 550, in increment
    raise six.reraise(type(error), error, _stacktrace)
  File "C:\Users\waard\Desktop\my-app\py\env_v3.8.12\lib\site-packages\urllib3\packages\six.py", line 770, in reraise
    raise value
  File "C:\Users\waard\Desktop\my-app\py\env_v3.8.12\lib\site-packages\urllib3\connectionpool.py", line 703, in urlopen
    httplib_response = self._make_request(
  File "C:\Users\waard\Desktop\my-app\py\env_v3.8.12\lib\site-packages\urllib3\connectionpool.py", line 451, in _make_request
    self._raise_timeout(err=e, url=url, timeout_value=read_timeout)
  File "C:\Users\waard\Desktop\my-app\py\env_v3.8.12\lib\site-packages\urllib3\connectionpool.py", line 340, in _raise_timeout
    raise ReadTimeoutError(
urllib3.exceptions.ReadTimeoutError: HTTPSConnectionPool(host='zozo.jp', port=443): Read timed out. (read timeout=7.5)

During handling of the above exception, another exception occurred:

Traceback (most recent call last):
  File "c:/Users/waard/Desktop/my-app/py/connect.py", line 186, in executeGetRequest
    res = requests.get(arrayList['crawlingurl'], timeout=(3.0, 7.5))
  File "C:\Users\waard\Desktop\my-app\py\env_v3.8.12\lib\site-packages\requests\api.py", line 75, in get
    return request('get', url, params=params, **kwargs)
  File "C:\Users\waard\Desktop\my-app\py\env_v3.8.12\lib\site-packages\requests\api.py", line 61, in request
    return session.request(method=method, url=url, **kwargs)
  File "C:\Users\waard\Desktop\my-app\py\env_v3.8.12\lib\site-packages\requests\sessions.py", line 529, in request
    resp = self.send(prep, **send_kwargs)
  File "C:\Users\waard\Desktop\my-app\py\env_v3.8.12\lib\site-packages\requests\sessions.py", line 645, in send
    r = adapter.send(request, **kwargs)
  File "C:\Users\waard\Desktop\my-app\py\env_v3.8.12\lib\site-packages\requests\adapters.py", line 532, in send
    raise ReadTimeout(e, request=request)
requests.exceptions.ReadTimeout: HTTPSConnectionPool(host='zozo.jp', port=443): Read timed out. (read timeout=7.5)

2022-01-14 01:55:28,230 <ERROR> :  occered at executeGetRequest Max retries exceeded with urlhttps://zozo.jp/brand/nike/shoes/sneakers/
2022-01-14 01:55:28,833 <ERROR> :  occered at executeGetRequest requests failed:https://www.jiji.com/jc/c?g=pol
2022-01-14 01:55:32,226 <ERROR> :  occered at executeGetRequest requests failed:https://www.jiji.com/jc/c?g=pol
2022-01-14 01:55:35,571 <ERROR> :  occered at executeGetRequest requests failed:https://www.jiji.com/jc/c?g=pol
2022-01-14 01:55:38,582 <ERROR> :  occered at executeGetRequest Max retries exceeded with urlhttps://www.jiji.com/jc/c?g=pol
2022-01-14 15:36:56,883 <ERROR> :  occered at executeGetRequest <class 'ValueError'>1
2022-01-14 15:36:56,884 <ERROR> : Traceback (most recent call last):
  File "c:/Users/waard/Desktop/my-app/py/connect.py", line 194, in executeGetRequest
    root = lxml.html.fromstring(html)
  File "C:\Users\waard\Desktop\my-app\py\env_v3.8.12\lib\site-packages\lxml\html\__init__.py", line 875, in fromstring
    doc = document_fromstring(html, parser=parser, base_url=base_url, **kw)
  File "C:\Users\waard\Desktop\my-app\py\env_v3.8.12\lib\site-packages\lxml\html\__init__.py", line 761, in document_fromstring
    value = etree.fromstring(html, parser, **kw)
  File "src\lxml\etree.pyx", line 3252, in lxml.etree.fromstring
  File "src\lxml\parser.pxi", line 1907, in lxml.etree._parseMemoryDocument
ValueError: Unicode strings with encoding declaration are not supported. Please use bytes input or XML fragments without declaration.

2022-01-14 15:38:03,091 <ERROR> :  occered at executeGetRequest <class 'requests.exceptions.ReadTimeout'>
2022-01-14 15:38:03,091 <ERROR> : Traceback (most recent call last):
  File "C:\Users\waard\Desktop\my-app\py\env_v3.8.12\lib\site-packages\urllib3\connectionpool.py", line 449, in _make_request
    six.raise_from(e, None)
  File "<string>", line 3, in raise_from
  File "C:\Users\waard\Desktop\my-app\py\env_v3.8.12\lib\site-packages\urllib3\connectionpool.py", line 444, in _make_request
    httplib_response = conn.getresponse()
  File "C:\Users\waard\anaconda3\lib\http\client.py", line 1348, in getresponse
    response.begin()
  File "C:\Users\waard\anaconda3\lib\http\client.py", line 316, in begin
    version, status, reason = self._read_status()
  File "C:\Users\waard\anaconda3\lib\http\client.py", line 277, in _read_status
    line = str(self.fp.readline(_MAXLINE + 1), "iso-8859-1")
  File "C:\Users\waard\anaconda3\lib\socket.py", line 669, in readinto
    return self._sock.recv_into(b)
  File "C:\Users\waard\anaconda3\lib\ssl.py", line 1241, in recv_into
    return self.read(nbytes, buffer)
  File "C:\Users\waard\anaconda3\lib\ssl.py", line 1099, in read
    return self._sslobj.read(len, buffer)
socket.timeout: The read operation timed out

During handling of the above exception, another exception occurred:

Traceback (most recent call last):
  File "C:\Users\waard\Desktop\my-app\py\env_v3.8.12\lib\site-packages\requests\adapters.py", line 440, in send
    resp = conn.urlopen(
  File "C:\Users\waard\Desktop\my-app\py\env_v3.8.12\lib\site-packages\urllib3\connectionpool.py", line 785, in urlopen
    retries = retries.increment(
  File "C:\Users\waard\Desktop\my-app\py\env_v3.8.12\lib\site-packages\urllib3\util\retry.py", line 550, in increment
    raise six.reraise(type(error), error, _stacktrace)
  File "C:\Users\waard\Desktop\my-app\py\env_v3.8.12\lib\site-packages\urllib3\packages\six.py", line 770, in reraise
    raise value
  File "C:\Users\waard\Desktop\my-app\py\env_v3.8.12\lib\site-packages\urllib3\connectionpool.py", line 703, in urlopen
    httplib_response = self._make_request(
  File "C:\Users\waard\Desktop\my-app\py\env_v3.8.12\lib\site-packages\urllib3\connectionpool.py", line 451, in _make_request
    self._raise_timeout(err=e, url=url, timeout_value=read_timeout)
  File "C:\Users\waard\Desktop\my-app\py\env_v3.8.12\lib\site-packages\urllib3\connectionpool.py", line 340, in _raise_timeout
    raise ReadTimeoutError(
urllib3.exceptions.ReadTimeoutError: HTTPSConnectionPool(host='zozo.jp', port=443): Read timed out. (read timeout=7.5)

During handling of the above exception, another exception occurred:

Traceback (most recent call last):
  File "c:/Users/waard/Desktop/my-app/py/connect.py", line 186, in executeGetRequest
    res = requests.get(arrayList['crawlingurl'], timeout=(3.0, 7.5))
  File "C:\Users\waard\Desktop\my-app\py\env_v3.8.12\lib\site-packages\requests\api.py", line 75, in get
    return request('get', url, params=params, **kwargs)
  File "C:\Users\waard\Desktop\my-app\py\env_v3.8.12\lib\site-packages\requests\api.py", line 61, in request
    return session.request(method=method, url=url, **kwargs)
  File "C:\Users\waard\Desktop\my-app\py\env_v3.8.12\lib\site-packages\requests\sessions.py", line 529, in request
    resp = self.send(prep, **send_kwargs)
  File "C:\Users\waard\Desktop\my-app\py\env_v3.8.12\lib\site-packages\requests\sessions.py", line 645, in send
    r = adapter.send(request, **kwargs)
  File "C:\Users\waard\Desktop\my-app\py\env_v3.8.12\lib\site-packages\requests\adapters.py", line 532, in send
    raise ReadTimeout(e, request=request)
requests.exceptions.ReadTimeout: HTTPSConnectionPool(host='zozo.jp', port=443): Read timed out. (read timeout=7.5)

2022-01-14 15:38:10,689 <ERROR> :  occered at executeGetRequest <class 'requests.exceptions.ReadTimeout'>
2022-01-14 15:38:10,689 <ERROR> : Traceback (most recent call last):
  File "C:\Users\waard\Desktop\my-app\py\env_v3.8.12\lib\site-packages\urllib3\connectionpool.py", line 449, in _make_request
    six.raise_from(e, None)
  File "<string>", line 3, in raise_from
  File "C:\Users\waard\Desktop\my-app\py\env_v3.8.12\lib\site-packages\urllib3\connectionpool.py", line 444, in _make_request
    httplib_response = conn.getresponse()
  File "C:\Users\waard\anaconda3\lib\http\client.py", line 1348, in getresponse
    response.begin()
  File "C:\Users\waard\anaconda3\lib\http\client.py", line 316, in begin
    version, status, reason = self._read_status()
  File "C:\Users\waard\anaconda3\lib\http\client.py", line 277, in _read_status
    line = str(self.fp.readline(_MAXLINE + 1), "iso-8859-1")
  File "C:\Users\waard\anaconda3\lib\socket.py", line 669, in readinto
    return self._sock.recv_into(b)
  File "C:\Users\waard\anaconda3\lib\ssl.py", line 1241, in recv_into
    return self.read(nbytes, buffer)
  File "C:\Users\waard\anaconda3\lib\ssl.py", line 1099, in read
    return self._sslobj.read(len, buffer)
socket.timeout: The read operation timed out

During handling of the above exception, another exception occurred:

Traceback (most recent call last):
  File "C:\Users\waard\Desktop\my-app\py\env_v3.8.12\lib\site-packages\requests\adapters.py", line 440, in send
    resp = conn.urlopen(
  File "C:\Users\waard\Desktop\my-app\py\env_v3.8.12\lib\site-packages\urllib3\connectionpool.py", line 785, in urlopen
    retries = retries.increment(
  File "C:\Users\waard\Desktop\my-app\py\env_v3.8.12\lib\site-packages\urllib3\util\retry.py", line 550, in increment
    raise six.reraise(type(error), error, _stacktrace)
  File "C:\Users\waard\Desktop\my-app\py\env_v3.8.12\lib\site-packages\urllib3\packages\six.py", line 770, in reraise
    raise value
  File "C:\Users\waard\Desktop\my-app\py\env_v3.8.12\lib\site-packages\urllib3\connectionpool.py", line 703, in urlopen
    httplib_response = self._make_request(
  File "C:\Users\waard\Desktop\my-app\py\env_v3.8.12\lib\site-packages\urllib3\connectionpool.py", line 451, in _make_request
    self._raise_timeout(err=e, url=url, timeout_value=read_timeout)
  File "C:\Users\waard\Desktop\my-app\py\env_v3.8.12\lib\site-packages\urllib3\connectionpool.py", line 340, in _raise_timeout
    raise ReadTimeoutError(
urllib3.exceptions.ReadTimeoutError: HTTPSConnectionPool(host='zozo.jp', port=443): Read timed out. (read timeout=7.5)

During handling of the above exception, another exception occurred:

Traceback (most recent call last):
  File "c:/Users/waard/Desktop/my-app/py/connect.py", line 186, in executeGetRequest
    res = requests.get(arrayList['crawlingurl'], timeout=(3.0, 7.5))
  File "C:\Users\waard\Desktop\my-app\py\env_v3.8.12\lib\site-packages\requests\api.py", line 75, in get
    return request('get', url, params=params, **kwargs)
  File "C:\Users\waard\Desktop\my-app\py\env_v3.8.12\lib\site-packages\requests\api.py", line 61, in request
    return session.request(method=method, url=url, **kwargs)
  File "C:\Users\waard\Desktop\my-app\py\env_v3.8.12\lib\site-packages\requests\sessions.py", line 529, in request
    resp = self.send(prep, **send_kwargs)
  File "C:\Users\waard\Desktop\my-app\py\env_v3.8.12\lib\site-packages\requests\sessions.py", line 645, in send
    r = adapter.send(request, **kwargs)
  File "C:\Users\waard\Desktop\my-app\py\env_v3.8.12\lib\site-packages\requests\adapters.py", line 532, in send
    raise ReadTimeout(e, request=request)
requests.exceptions.ReadTimeout: HTTPSConnectionPool(host='zozo.jp', port=443): Read timed out. (read timeout=7.5)

2022-01-14 15:38:18,260 <ERROR> :  occered at executeGetRequest <class 'requests.exceptions.ReadTimeout'>
2022-01-14 15:38:18,260 <ERROR> : Traceback (most recent call last):
  File "C:\Users\waard\Desktop\my-app\py\env_v3.8.12\lib\site-packages\urllib3\connectionpool.py", line 449, in _make_request
    six.raise_from(e, None)
  File "<string>", line 3, in raise_from
  File "C:\Users\waard\Desktop\my-app\py\env_v3.8.12\lib\site-packages\urllib3\connectionpool.py", line 444, in _make_request
    httplib_response = conn.getresponse()
  File "C:\Users\waard\anaconda3\lib\http\client.py", line 1348, in getresponse
    response.begin()
  File "C:\Users\waard\anaconda3\lib\http\client.py", line 316, in begin
    version, status, reason = self._read_status()
  File "C:\Users\waard\anaconda3\lib\http\client.py", line 277, in _read_status
    line = str(self.fp.readline(_MAXLINE + 1), "iso-8859-1")
  File "C:\Users\waard\anaconda3\lib\socket.py", line 669, in readinto
    return self._sock.recv_into(b)
  File "C:\Users\waard\anaconda3\lib\ssl.py", line 1241, in recv_into
    return self.read(nbytes, buffer)
  File "C:\Users\waard\anaconda3\lib\ssl.py", line 1099, in read
    return self._sslobj.read(len, buffer)
socket.timeout: The read operation timed out

During handling of the above exception, another exception occurred:

Traceback (most recent call last):
  File "C:\Users\waard\Desktop\my-app\py\env_v3.8.12\lib\site-packages\requests\adapters.py", line 440, in send
    resp = conn.urlopen(
  File "C:\Users\waard\Desktop\my-app\py\env_v3.8.12\lib\site-packages\urllib3\connectionpool.py", line 785, in urlopen
    retries = retries.increment(
  File "C:\Users\waard\Desktop\my-app\py\env_v3.8.12\lib\site-packages\urllib3\util\retry.py", line 550, in increment
    raise six.reraise(type(error), error, _stacktrace)
  File "C:\Users\waard\Desktop\my-app\py\env_v3.8.12\lib\site-packages\urllib3\packages\six.py", line 770, in reraise
    raise value
  File "C:\Users\waard\Desktop\my-app\py\env_v3.8.12\lib\site-packages\urllib3\connectionpool.py", line 703, in urlopen
    httplib_response = self._make_request(
  File "C:\Users\waard\Desktop\my-app\py\env_v3.8.12\lib\site-packages\urllib3\connectionpool.py", line 451, in _make_request
    self._raise_timeout(err=e, url=url, timeout_value=read_timeout)
  File "C:\Users\waard\Desktop\my-app\py\env_v3.8.12\lib\site-packages\urllib3\connectionpool.py", line 340, in _raise_timeout
    raise ReadTimeoutError(
urllib3.exceptions.ReadTimeoutError: HTTPSConnectionPool(host='zozo.jp', port=443): Read timed out. (read timeout=7.5)

During handling of the above exception, another exception occurred:

Traceback (most recent call last):
  File "c:/Users/waard/Desktop/my-app/py/connect.py", line 186, in executeGetRequest
    res = requests.get(arrayList['crawlingurl'], timeout=(3.0, 7.5))
  File "C:\Users\waard\Desktop\my-app\py\env_v3.8.12\lib\site-packages\requests\api.py", line 75, in get
    return request('get', url, params=params, **kwargs)
  File "C:\Users\waard\Desktop\my-app\py\env_v3.8.12\lib\site-packages\requests\api.py", line 61, in request
    return session.request(method=method, url=url, **kwargs)
  File "C:\Users\waard\Desktop\my-app\py\env_v3.8.12\lib\site-packages\requests\sessions.py", line 529, in request
    resp = self.send(prep, **send_kwargs)
  File "C:\Users\waard\Desktop\my-app\py\env_v3.8.12\lib\site-packages\requests\sessions.py", line 645, in send
    r = adapter.send(request, **kwargs)
  File "C:\Users\waard\Desktop\my-app\py\env_v3.8.12\lib\site-packages\requests\adapters.py", line 532, in send
    raise ReadTimeout(e, request=request)
requests.exceptions.ReadTimeout: HTTPSConnectionPool(host='zozo.jp', port=443): Read timed out. (read timeout=7.5)

2022-01-14 15:38:18,298 <ERROR> :  occered at executeGetRequest Max retries exceeded with urlhttps://zozo.jp/brand/nike/shoes/sneakers/
2022-01-14 15:38:18,866 <ERROR> :  occered at executeGetRequest requests failed:https://www.jiji.com/jc/c?g=pol
2022-01-14 15:38:22,210 <ERROR> :  occered at executeGetRequest requests failed:https://www.jiji.com/jc/c?g=pol
2022-01-14 15:38:25,606 <ERROR> :  occered at executeGetRequest requests failed:https://www.jiji.com/jc/c?g=pol
2022-01-14 15:38:28,609 <ERROR> :  occered at executeGetRequest Max retries exceeded with urlhttps://www.jiji.com/jc/c?g=pol
2022-01-14 16:11:39,527 <ERROR> :  occered at executeGetRequest <class 'ValueError'>1
2022-01-14 16:11:39,527 <ERROR> : Traceback (most recent call last):
  File "./py/connect.py", line 194, in executeGetRequest
    root = lxml.html.fromstring(html)
  File "C:\Users\waard\anaconda3\lib\site-packages\lxml\html\__init__.py", line 875, in fromstring
    doc = document_fromstring(html, parser=parser, base_url=base_url, **kw)
  File "C:\Users\waard\anaconda3\lib\site-packages\lxml\html\__init__.py", line 761, in document_fromstring
    value = etree.fromstring(html, parser, **kw)
  File "src/lxml/etree.pyx", line 3237, in lxml.etree.fromstring
  File "src/lxml/parser.pxi", line 1891, in lxml.etree._parseMemoryDocument
ValueError: Unicode strings with encoding declaration are not supported. Please use bytes input or XML fragments without declaration.

2022-01-14 16:12:50,536 <ERROR> :  occered at executeGetRequest <class 'requests.exceptions.ReadTimeout'>
2022-01-14 16:12:50,536 <ERROR> : Traceback (most recent call last):
  File "C:\Users\waard\anaconda3\lib\site-packages\urllib3\connectionpool.py", line 445, in _make_request
    six.raise_from(e, None)
  File "<string>", line 3, in raise_from
  File "C:\Users\waard\anaconda3\lib\site-packages\urllib3\connectionpool.py", line 440, in _make_request
    httplib_response = conn.getresponse()
  File "C:\Users\waard\anaconda3\lib\http\client.py", line 1348, in getresponse
    response.begin()
  File "C:\Users\waard\anaconda3\lib\http\client.py", line 316, in begin
    version, status, reason = self._read_status()
  File "C:\Users\waard\anaconda3\lib\http\client.py", line 277, in _read_status
    line = str(self.fp.readline(_MAXLINE + 1), "iso-8859-1")
  File "C:\Users\waard\anaconda3\lib\socket.py", line 669, in readinto
    return self._sock.recv_into(b)
  File "C:\Users\waard\anaconda3\lib\ssl.py", line 1241, in recv_into
    return self.read(nbytes, buffer)
  File "C:\Users\waard\anaconda3\lib\ssl.py", line 1099, in read
    return self._sslobj.read(len, buffer)
socket.timeout: The read operation timed out

During handling of the above exception, another exception occurred:

Traceback (most recent call last):
  File "C:\Users\waard\anaconda3\lib\site-packages\requests\adapters.py", line 440, in send
    resp = conn.urlopen(
  File "C:\Users\waard\anaconda3\lib\site-packages\urllib3\connectionpool.py", line 755, in urlopen
    retries = retries.increment(
  File "C:\Users\waard\anaconda3\lib\site-packages\urllib3\util\retry.py", line 532, in increment
    raise six.reraise(type(error), error, _stacktrace)
  File "C:\Users\waard\anaconda3\lib\site-packages\urllib3\packages\six.py", line 770, in reraise
    raise value
  File "C:\Users\waard\anaconda3\lib\site-packages\urllib3\connectionpool.py", line 699, in urlopen
    httplib_response = self._make_request(
  File "C:\Users\waard\anaconda3\lib\site-packages\urllib3\connectionpool.py", line 447, in _make_request
    self._raise_timeout(err=e, url=url, timeout_value=read_timeout)
  File "C:\Users\waard\anaconda3\lib\site-packages\urllib3\connectionpool.py", line 336, in _raise_timeout
    raise ReadTimeoutError(
urllib3.exceptions.ReadTimeoutError: HTTPSConnectionPool(host='zozo.jp', port=443): Read timed out. (read timeout=7.5)

During handling of the above exception, another exception occurred:

Traceback (most recent call last):
  File "./py/connect.py", line 186, in executeGetRequest
    res = requests.get(arrayList['crawlingurl'], timeout=(3.0, 7.5))
  File "C:\Users\waard\anaconda3\lib\site-packages\requests\api.py", line 75, in get
    return request('get', url, params=params, **kwargs)
  File "C:\Users\waard\anaconda3\lib\site-packages\requests\api.py", line 61, in request
    return session.request(method=method, url=url, **kwargs)
  File "C:\Users\waard\anaconda3\lib\site-packages\requests\sessions.py", line 529, in request
    resp = self.send(prep, **send_kwargs)
  File "C:\Users\waard\anaconda3\lib\site-packages\requests\sessions.py", line 645, in send
    r = adapter.send(request, **kwargs)
  File "C:\Users\waard\anaconda3\lib\site-packages\requests\adapters.py", line 532, in send
    raise ReadTimeout(e, request=request)
requests.exceptions.ReadTimeout: HTTPSConnectionPool(host='zozo.jp', port=443): Read timed out. (read timeout=7.5)

2022-01-14 16:12:58,129 <ERROR> :  occered at executeGetRequest <class 'requests.exceptions.ReadTimeout'>
2022-01-14 16:12:58,129 <ERROR> : Traceback (most recent call last):
  File "C:\Users\waard\anaconda3\lib\site-packages\urllib3\connectionpool.py", line 445, in _make_request
    six.raise_from(e, None)
  File "<string>", line 3, in raise_from
  File "C:\Users\waard\anaconda3\lib\site-packages\urllib3\connectionpool.py", line 440, in _make_request
    httplib_response = conn.getresponse()
  File "C:\Users\waard\anaconda3\lib\http\client.py", line 1348, in getresponse
    response.begin()
  File "C:\Users\waard\anaconda3\lib\http\client.py", line 316, in begin
    version, status, reason = self._read_status()
  File "C:\Users\waard\anaconda3\lib\http\client.py", line 277, in _read_status
    line = str(self.fp.readline(_MAXLINE + 1), "iso-8859-1")
  File "C:\Users\waard\anaconda3\lib\socket.py", line 669, in readinto
    return self._sock.recv_into(b)
  File "C:\Users\waard\anaconda3\lib\ssl.py", line 1241, in recv_into
    return self.read(nbytes, buffer)
  File "C:\Users\waard\anaconda3\lib\ssl.py", line 1099, in read
    return self._sslobj.read(len, buffer)
socket.timeout: The read operation timed out

During handling of the above exception, another exception occurred:

Traceback (most recent call last):
  File "C:\Users\waard\anaconda3\lib\site-packages\requests\adapters.py", line 440, in send
    resp = conn.urlopen(
  File "C:\Users\waard\anaconda3\lib\site-packages\urllib3\connectionpool.py", line 755, in urlopen
    retries = retries.increment(
  File "C:\Users\waard\anaconda3\lib\site-packages\urllib3\util\retry.py", line 532, in increment
    raise six.reraise(type(error), error, _stacktrace)
  File "C:\Users\waard\anaconda3\lib\site-packages\urllib3\packages\six.py", line 770, in reraise
    raise value
  File "C:\Users\waard\anaconda3\lib\site-packages\urllib3\connectionpool.py", line 699, in urlopen
    httplib_response = self._make_request(
  File "C:\Users\waard\anaconda3\lib\site-packages\urllib3\connectionpool.py", line 447, in _make_request
    self._raise_timeout(err=e, url=url, timeout_value=read_timeout)
  File "C:\Users\waard\anaconda3\lib\site-packages\urllib3\connectionpool.py", line 336, in _raise_timeout
    raise ReadTimeoutError(
urllib3.exceptions.ReadTimeoutError: HTTPSConnectionPool(host='zozo.jp', port=443): Read timed out. (read timeout=7.5)

During handling of the above exception, another exception occurred:

Traceback (most recent call last):
  File "./py/connect.py", line 186, in executeGetRequest
    res = requests.get(arrayList['crawlingurl'], timeout=(3.0, 7.5))
  File "C:\Users\waard\anaconda3\lib\site-packages\requests\api.py", line 75, in get
    return request('get', url, params=params, **kwargs)
  File "C:\Users\waard\anaconda3\lib\site-packages\requests\api.py", line 61, in request
    return session.request(method=method, url=url, **kwargs)
  File "C:\Users\waard\anaconda3\lib\site-packages\requests\sessions.py", line 529, in request
    resp = self.send(prep, **send_kwargs)
  File "C:\Users\waard\anaconda3\lib\site-packages\requests\sessions.py", line 645, in send
    r = adapter.send(request, **kwargs)
  File "C:\Users\waard\anaconda3\lib\site-packages\requests\adapters.py", line 532, in send
    raise ReadTimeout(e, request=request)
requests.exceptions.ReadTimeout: HTTPSConnectionPool(host='zozo.jp', port=443): Read timed out. (read timeout=7.5)

2022-01-14 16:13:05,722 <ERROR> :  occered at executeGetRequest <class 'requests.exceptions.ReadTimeout'>
2022-01-14 16:13:05,722 <ERROR> : Traceback (most recent call last):
  File "C:\Users\waard\anaconda3\lib\site-packages\urllib3\connectionpool.py", line 445, in _make_request
    six.raise_from(e, None)
  File "<string>", line 3, in raise_from
  File "C:\Users\waard\anaconda3\lib\site-packages\urllib3\connectionpool.py", line 440, in _make_request
    httplib_response = conn.getresponse()
  File "C:\Users\waard\anaconda3\lib\http\client.py", line 1348, in getresponse
    response.begin()
  File "C:\Users\waard\anaconda3\lib\http\client.py", line 316, in begin
    version, status, reason = self._read_status()
  File "C:\Users\waard\anaconda3\lib\http\client.py", line 277, in _read_status
    line = str(self.fp.readline(_MAXLINE + 1), "iso-8859-1")
  File "C:\Users\waard\anaconda3\lib\socket.py", line 669, in readinto
    return self._sock.recv_into(b)
  File "C:\Users\waard\anaconda3\lib\ssl.py", line 1241, in recv_into
    return self.read(nbytes, buffer)
  File "C:\Users\waard\anaconda3\lib\ssl.py", line 1099, in read
    return self._sslobj.read(len, buffer)
socket.timeout: The read operation timed out

During handling of the above exception, another exception occurred:

Traceback (most recent call last):
  File "C:\Users\waard\anaconda3\lib\site-packages\requests\adapters.py", line 440, in send
    resp = conn.urlopen(
  File "C:\Users\waard\anaconda3\lib\site-packages\urllib3\connectionpool.py", line 755, in urlopen
    retries = retries.increment(
  File "C:\Users\waard\anaconda3\lib\site-packages\urllib3\util\retry.py", line 532, in increment
    raise six.reraise(type(error), error, _stacktrace)
  File "C:\Users\waard\anaconda3\lib\site-packages\urllib3\packages\six.py", line 770, in reraise
    raise value
  File "C:\Users\waard\anaconda3\lib\site-packages\urllib3\connectionpool.py", line 699, in urlopen
    httplib_response = self._make_request(
  File "C:\Users\waard\anaconda3\lib\site-packages\urllib3\connectionpool.py", line 447, in _make_request
    self._raise_timeout(err=e, url=url, timeout_value=read_timeout)
  File "C:\Users\waard\anaconda3\lib\site-packages\urllib3\connectionpool.py", line 336, in _raise_timeout
    raise ReadTimeoutError(
urllib3.exceptions.ReadTimeoutError: HTTPSConnectionPool(host='zozo.jp', port=443): Read timed out. (read timeout=7.5)

During handling of the above exception, another exception occurred:

Traceback (most recent call last):
  File "./py/connect.py", line 186, in executeGetRequest
    res = requests.get(arrayList['crawlingurl'], timeout=(3.0, 7.5))
  File "C:\Users\waard\anaconda3\lib\site-packages\requests\api.py", line 75, in get
    return request('get', url, params=params, **kwargs)
  File "C:\Users\waard\anaconda3\lib\site-packages\requests\api.py", line 61, in request
    return session.request(method=method, url=url, **kwargs)
  File "C:\Users\waard\anaconda3\lib\site-packages\requests\sessions.py", line 529, in request
    resp = self.send(prep, **send_kwargs)
  File "C:\Users\waard\anaconda3\lib\site-packages\requests\sessions.py", line 645, in send
    r = adapter.send(request, **kwargs)
  File "C:\Users\waard\anaconda3\lib\site-packages\requests\adapters.py", line 532, in send
    raise ReadTimeout(e, request=request)
requests.exceptions.ReadTimeout: HTTPSConnectionPool(host='zozo.jp', port=443): Read timed out. (read timeout=7.5)

2022-01-14 16:13:05,722 <ERROR> :  occered at executeGetRequest Max retries exceeded with urlhttps://zozo.jp/brand/nike/shoes/sneakers/
2022-01-14 16:13:06,366 <ERROR> :  occered at executeGetRequest requests failed:https://www.jiji.com/jc/c?g=pol
2022-01-14 16:13:09,868 <ERROR> :  occered at executeGetRequest requests failed:https://www.jiji.com/jc/c?g=pol
2022-01-14 16:13:13,379 <ERROR> :  occered at executeGetRequest requests failed:https://www.jiji.com/jc/c?g=pol
2022-01-14 16:13:16,391 <ERROR> :  occered at executeGetRequest Max retries exceeded with urlhttps://www.jiji.com/jc/c?g=pol
2022-01-14 16:30:19,828 <ERROR> :  occered at executeGetRequest <class 'ValueError'>1
2022-01-14 16:30:19,828 <ERROR> : Traceback (most recent call last):
  File "c:/Users/waard/Desktop/my-app/py/connect.py", line 194, in executeGetRequest
    root = lxml.html.fromstring(html)
  File "C:\Users\waard\Desktop\my-app\py\env_v3.8.12\lib\site-packages\lxml\html\__init__.py", line 875, in fromstring
    doc = document_fromstring(html, parser=parser, base_url=base_url, **kw)
  File "C:\Users\waard\Desktop\my-app\py\env_v3.8.12\lib\site-packages\lxml\html\__init__.py", line 761, in document_fromstring
    value = etree.fromstring(html, parser, **kw)
  File "src\lxml\etree.pyx", line 3252, in lxml.etree.fromstring
  File "src\lxml\parser.pxi", line 1907, in lxml.etree._parseMemoryDocument
ValueError: Unicode strings with encoding declaration are not supported. Please use bytes input or XML fragments without declaration.

2022-01-14 16:31:08,858 <ERROR> :  occered at executeGetRequest <class 'requests.exceptions.ReadTimeout'>
2022-01-14 16:31:08,858 <ERROR> : Traceback (most recent call last):
  File "C:\Users\waard\Desktop\my-app\py\env_v3.8.12\lib\site-packages\urllib3\connectionpool.py", line 449, in _make_request
    six.raise_from(e, None)
  File "<string>", line 3, in raise_from
  File "C:\Users\waard\Desktop\my-app\py\env_v3.8.12\lib\site-packages\urllib3\connectionpool.py", line 444, in _make_request
    httplib_response = conn.getresponse()
  File "C:\Users\waard\anaconda3\lib\http\client.py", line 1348, in getresponse
    response.begin()
  File "C:\Users\waard\anaconda3\lib\http\client.py", line 316, in begin
    version, status, reason = self._read_status()
  File "C:\Users\waard\anaconda3\lib\http\client.py", line 277, in _read_status
    line = str(self.fp.readline(_MAXLINE + 1), "iso-8859-1")
  File "C:\Users\waard\anaconda3\lib\socket.py", line 669, in readinto
    return self._sock.recv_into(b)
  File "C:\Users\waard\anaconda3\lib\ssl.py", line 1241, in recv_into
    return self.read(nbytes, buffer)
  File "C:\Users\waard\anaconda3\lib\ssl.py", line 1099, in read
    return self._sslobj.read(len, buffer)
socket.timeout: The read operation timed out

During handling of the above exception, another exception occurred:

Traceback (most recent call last):
  File "C:\Users\waard\Desktop\my-app\py\env_v3.8.12\lib\site-packages\requests\adapters.py", line 440, in send
    resp = conn.urlopen(
  File "C:\Users\waard\Desktop\my-app\py\env_v3.8.12\lib\site-packages\urllib3\connectionpool.py", line 785, in urlopen
    retries = retries.increment(
  File "C:\Users\waard\Desktop\my-app\py\env_v3.8.12\lib\site-packages\urllib3\util\retry.py", line 550, in increment
    raise six.reraise(type(error), error, _stacktrace)
  File "C:\Users\waard\Desktop\my-app\py\env_v3.8.12\lib\site-packages\urllib3\packages\six.py", line 770, in reraise
    raise value
  File "C:\Users\waard\Desktop\my-app\py\env_v3.8.12\lib\site-packages\urllib3\connectionpool.py", line 703, in urlopen
    httplib_response = self._make_request(
  File "C:\Users\waard\Desktop\my-app\py\env_v3.8.12\lib\site-packages\urllib3\connectionpool.py", line 451, in _make_request
    self._raise_timeout(err=e, url=url, timeout_value=read_timeout)
  File "C:\Users\waard\Desktop\my-app\py\env_v3.8.12\lib\site-packages\urllib3\connectionpool.py", line 340, in _raise_timeout
    raise ReadTimeoutError(
urllib3.exceptions.ReadTimeoutError: HTTPSConnectionPool(host='zozo.jp', port=443): Read timed out. (read timeout=7.5)

During handling of the above exception, another exception occurred:

Traceback (most recent call last):
  File "c:/Users/waard/Desktop/my-app/py/connect.py", line 186, in executeGetRequest
    res = requests.get(arrayList['crawlingurl'], timeout=(3.0, 7.5))
  File "C:\Users\waard\Desktop\my-app\py\env_v3.8.12\lib\site-packages\requests\api.py", line 75, in get
    return request('get', url, params=params, **kwargs)
  File "C:\Users\waard\Desktop\my-app\py\env_v3.8.12\lib\site-packages\requests\api.py", line 61, in request
    return session.request(method=method, url=url, **kwargs)
  File "C:\Users\waard\Desktop\my-app\py\env_v3.8.12\lib\site-packages\requests\sessions.py", line 529, in request
    resp = self.send(prep, **send_kwargs)
  File "C:\Users\waard\Desktop\my-app\py\env_v3.8.12\lib\site-packages\requests\sessions.py", line 645, in send
    r = adapter.send(request, **kwargs)
  File "C:\Users\waard\Desktop\my-app\py\env_v3.8.12\lib\site-packages\requests\adapters.py", line 532, in send
    raise ReadTimeout(e, request=request)
requests.exceptions.ReadTimeout: HTTPSConnectionPool(host='zozo.jp', port=443): Read timed out. (read timeout=7.5)

2022-01-14 16:31:16,444 <ERROR> :  occered at executeGetRequest <class 'requests.exceptions.ReadTimeout'>
2022-01-14 16:31:16,445 <ERROR> : Traceback (most recent call last):
  File "C:\Users\waard\Desktop\my-app\py\env_v3.8.12\lib\site-packages\urllib3\connectionpool.py", line 449, in _make_request
    six.raise_from(e, None)
  File "<string>", line 3, in raise_from
  File "C:\Users\waard\Desktop\my-app\py\env_v3.8.12\lib\site-packages\urllib3\connectionpool.py", line 444, in _make_request
    httplib_response = conn.getresponse()
  File "C:\Users\waard\anaconda3\lib\http\client.py", line 1348, in getresponse
    response.begin()
  File "C:\Users\waard\anaconda3\lib\http\client.py", line 316, in begin
    version, status, reason = self._read_status()
  File "C:\Users\waard\anaconda3\lib\http\client.py", line 277, in _read_status
    line = str(self.fp.readline(_MAXLINE + 1), "iso-8859-1")
  File "C:\Users\waard\anaconda3\lib\socket.py", line 669, in readinto
    return self._sock.recv_into(b)
  File "C:\Users\waard\anaconda3\lib\ssl.py", line 1241, in recv_into
    return self.read(nbytes, buffer)
  File "C:\Users\waard\anaconda3\lib\ssl.py", line 1099, in read
    return self._sslobj.read(len, buffer)
socket.timeout: The read operation timed out

During handling of the above exception, another exception occurred:

Traceback (most recent call last):
  File "C:\Users\waard\Desktop\my-app\py\env_v3.8.12\lib\site-packages\requests\adapters.py", line 440, in send
    resp = conn.urlopen(
  File "C:\Users\waard\Desktop\my-app\py\env_v3.8.12\lib\site-packages\urllib3\connectionpool.py", line 785, in urlopen
    retries = retries.increment(
  File "C:\Users\waard\Desktop\my-app\py\env_v3.8.12\lib\site-packages\urllib3\util\retry.py", line 550, in increment
    raise six.reraise(type(error), error, _stacktrace)
  File "C:\Users\waard\Desktop\my-app\py\env_v3.8.12\lib\site-packages\urllib3\packages\six.py", line 770, in reraise
    raise value
  File "C:\Users\waard\Desktop\my-app\py\env_v3.8.12\lib\site-packages\urllib3\connectionpool.py", line 703, in urlopen
    httplib_response = self._make_request(
  File "C:\Users\waard\Desktop\my-app\py\env_v3.8.12\lib\site-packages\urllib3\connectionpool.py", line 451, in _make_request
    self._raise_timeout(err=e, url=url, timeout_value=read_timeout)
  File "C:\Users\waard\Desktop\my-app\py\env_v3.8.12\lib\site-packages\urllib3\connectionpool.py", line 340, in _raise_timeout
    raise ReadTimeoutError(
urllib3.exceptions.ReadTimeoutError: HTTPSConnectionPool(host='zozo.jp', port=443): Read timed out. (read timeout=7.5)

During handling of the above exception, another exception occurred:

Traceback (most recent call last):
  File "c:/Users/waard/Desktop/my-app/py/connect.py", line 186, in executeGetRequest
    res = requests.get(arrayList['crawlingurl'], timeout=(3.0, 7.5))
  File "C:\Users\waard\Desktop\my-app\py\env_v3.8.12\lib\site-packages\requests\api.py", line 75, in get
    return request('get', url, params=params, **kwargs)
  File "C:\Users\waard\Desktop\my-app\py\env_v3.8.12\lib\site-packages\requests\api.py", line 61, in request
    return session.request(method=method, url=url, **kwargs)
  File "C:\Users\waard\Desktop\my-app\py\env_v3.8.12\lib\site-packages\requests\sessions.py", line 529, in request
    resp = self.send(prep, **send_kwargs)
  File "C:\Users\waard\Desktop\my-app\py\env_v3.8.12\lib\site-packages\requests\sessions.py", line 645, in send
    r = adapter.send(request, **kwargs)
  File "C:\Users\waard\Desktop\my-app\py\env_v3.8.12\lib\site-packages\requests\adapters.py", line 532, in send
    raise ReadTimeout(e, request=request)
requests.exceptions.ReadTimeout: HTTPSConnectionPool(host='zozo.jp', port=443): Read timed out. (read timeout=7.5)

2022-01-14 16:31:24,024 <ERROR> :  occered at executeGetRequest <class 'requests.exceptions.ReadTimeout'>
2022-01-14 16:31:24,024 <ERROR> : Traceback (most recent call last):
  File "C:\Users\waard\Desktop\my-app\py\env_v3.8.12\lib\site-packages\urllib3\connectionpool.py", line 449, in _make_request
    six.raise_from(e, None)
  File "<string>", line 3, in raise_from
  File "C:\Users\waard\Desktop\my-app\py\env_v3.8.12\lib\site-packages\urllib3\connectionpool.py", line 444, in _make_request
    httplib_response = conn.getresponse()
  File "C:\Users\waard\anaconda3\lib\http\client.py", line 1348, in getresponse
    response.begin()
  File "C:\Users\waard\anaconda3\lib\http\client.py", line 316, in begin
    version, status, reason = self._read_status()
  File "C:\Users\waard\anaconda3\lib\http\client.py", line 277, in _read_status
    line = str(self.fp.readline(_MAXLINE + 1), "iso-8859-1")
  File "C:\Users\waard\anaconda3\lib\socket.py", line 669, in readinto
    return self._sock.recv_into(b)
  File "C:\Users\waard\anaconda3\lib\ssl.py", line 1241, in recv_into
    return self.read(nbytes, buffer)
  File "C:\Users\waard\anaconda3\lib\ssl.py", line 1099, in read
    return self._sslobj.read(len, buffer)
socket.timeout: The read operation timed out

During handling of the above exception, another exception occurred:

Traceback (most recent call last):
  File "C:\Users\waard\Desktop\my-app\py\env_v3.8.12\lib\site-packages\requests\adapters.py", line 440, in send
    resp = conn.urlopen(
  File "C:\Users\waard\Desktop\my-app\py\env_v3.8.12\lib\site-packages\urllib3\connectionpool.py", line 785, in urlopen
    retries = retries.increment(
  File "C:\Users\waard\Desktop\my-app\py\env_v3.8.12\lib\site-packages\urllib3\util\retry.py", line 550, in increment
    raise six.reraise(type(error), error, _stacktrace)
  File "C:\Users\waard\Desktop\my-app\py\env_v3.8.12\lib\site-packages\urllib3\packages\six.py", line 770, in reraise
    raise value
  File "C:\Users\waard\Desktop\my-app\py\env_v3.8.12\lib\site-packages\urllib3\connectionpool.py", line 703, in urlopen
    httplib_response = self._make_request(
  File "C:\Users\waard\Desktop\my-app\py\env_v3.8.12\lib\site-packages\urllib3\connectionpool.py", line 451, in _make_request
    self._raise_timeout(err=e, url=url, timeout_value=read_timeout)
  File "C:\Users\waard\Desktop\my-app\py\env_v3.8.12\lib\site-packages\urllib3\connectionpool.py", line 340, in _raise_timeout
    raise ReadTimeoutError(
urllib3.exceptions.ReadTimeoutError: HTTPSConnectionPool(host='zozo.jp', port=443): Read timed out. (read timeout=7.5)

During handling of the above exception, another exception occurred:

Traceback (most recent call last):
  File "c:/Users/waard/Desktop/my-app/py/connect.py", line 186, in executeGetRequest
    res = requests.get(arrayList['crawlingurl'], timeout=(3.0, 7.5))
  File "C:\Users\waard\Desktop\my-app\py\env_v3.8.12\lib\site-packages\requests\api.py", line 75, in get
    return request('get', url, params=params, **kwargs)
  File "C:\Users\waard\Desktop\my-app\py\env_v3.8.12\lib\site-packages\requests\api.py", line 61, in request
    return session.request(method=method, url=url, **kwargs)
  File "C:\Users\waard\Desktop\my-app\py\env_v3.8.12\lib\site-packages\requests\sessions.py", line 529, in request
    resp = self.send(prep, **send_kwargs)
  File "C:\Users\waard\Desktop\my-app\py\env_v3.8.12\lib\site-packages\requests\sessions.py", line 645, in send
    r = adapter.send(request, **kwargs)
  File "C:\Users\waard\Desktop\my-app\py\env_v3.8.12\lib\site-packages\requests\adapters.py", line 532, in send
    raise ReadTimeout(e, request=request)
requests.exceptions.ReadTimeout: HTTPSConnectionPool(host='zozo.jp', port=443): Read timed out. (read timeout=7.5)

2022-01-14 16:31:24,024 <ERROR> :  occered at executeGetRequest Max retries exceeded with urlhttps://zozo.jp/brand/nike/shoes/sneakers/
2022-01-14 16:31:24,500 <ERROR> :  occered at executeGetRequest requests failed:https://www.jiji.com/jc/c?g=pol
2022-01-14 16:31:27,880 <ERROR> :  occered at executeGetRequest requests failed:https://www.jiji.com/jc/c?g=pol
2022-01-14 16:31:31,230 <ERROR> :  occered at executeGetRequest requests failed:https://www.jiji.com/jc/c?g=pol
2022-01-14 16:31:34,243 <ERROR> :  occered at executeGetRequest Max retries exceeded with urlhttps://www.jiji.com/jc/c?g=pol
2022-01-14 16:36:20,956 <ERROR> :  occered at executeGetRequest <class 'ValueError'>1
2022-01-14 16:36:20,956 <ERROR> : Traceback (most recent call last):
  File "./py/connect.py", line 194, in executeGetRequest
    root = lxml.html.fromstring(html)
  File "C:\Users\waard\Desktop\my-app\py\env_v3.8.12\lib\site-packages\lxml\html\__init__.py", line 875, in fromstring
    doc = document_fromstring(html, parser=parser, base_url=base_url, **kw)
  File "C:\Users\waard\Desktop\my-app\py\env_v3.8.12\lib\site-packages\lxml\html\__init__.py", line 761, in document_fromstring
    value = etree.fromstring(html, parser, **kw)
  File "src\lxml\etree.pyx", line 3252, in lxml.etree.fromstring
  File "src\lxml\parser.pxi", line 1907, in lxml.etree._parseMemoryDocument
ValueError: Unicode strings with encoding declaration are not supported. Please use bytes input or XML fragments without declaration.

2022-01-14 16:37:12,474 <ERROR> :  occered at executeGetRequest <class 'requests.exceptions.ReadTimeout'>
2022-01-14 16:37:12,475 <ERROR> : Traceback (most recent call last):
  File "C:\Users\waard\Desktop\my-app\py\env_v3.8.12\lib\site-packages\urllib3\connectionpool.py", line 449, in _make_request
    six.raise_from(e, None)
  File "<string>", line 3, in raise_from
  File "C:\Users\waard\Desktop\my-app\py\env_v3.8.12\lib\site-packages\urllib3\connectionpool.py", line 444, in _make_request
    httplib_response = conn.getresponse()
  File "C:\Users\waard\anaconda3\lib\http\client.py", line 1348, in getresponse
    response.begin()
  File "C:\Users\waard\anaconda3\lib\http\client.py", line 316, in begin
    version, status, reason = self._read_status()
  File "C:\Users\waard\anaconda3\lib\http\client.py", line 277, in _read_status
    line = str(self.fp.readline(_MAXLINE + 1), "iso-8859-1")
  File "C:\Users\waard\anaconda3\lib\socket.py", line 669, in readinto
    return self._sock.recv_into(b)
  File "C:\Users\waard\anaconda3\lib\ssl.py", line 1241, in recv_into
    return self.read(nbytes, buffer)
  File "C:\Users\waard\anaconda3\lib\ssl.py", line 1099, in read
    return self._sslobj.read(len, buffer)
socket.timeout: The read operation timed out

During handling of the above exception, another exception occurred:

Traceback (most recent call last):
  File "C:\Users\waard\Desktop\my-app\py\env_v3.8.12\lib\site-packages\requests\adapters.py", line 440, in send
    resp = conn.urlopen(
  File "C:\Users\waard\Desktop\my-app\py\env_v3.8.12\lib\site-packages\urllib3\connectionpool.py", line 785, in urlopen
    retries = retries.increment(
  File "C:\Users\waard\Desktop\my-app\py\env_v3.8.12\lib\site-packages\urllib3\util\retry.py", line 550, in increment
    raise six.reraise(type(error), error, _stacktrace)
  File "C:\Users\waard\Desktop\my-app\py\env_v3.8.12\lib\site-packages\urllib3\packages\six.py", line 770, in reraise
    raise value
  File "C:\Users\waard\Desktop\my-app\py\env_v3.8.12\lib\site-packages\urllib3\connectionpool.py", line 703, in urlopen
    httplib_response = self._make_request(
  File "C:\Users\waard\Desktop\my-app\py\env_v3.8.12\lib\site-packages\urllib3\connectionpool.py", line 451, in _make_request
    self._raise_timeout(err=e, url=url, timeout_value=read_timeout)
  File "C:\Users\waard\Desktop\my-app\py\env_v3.8.12\lib\site-packages\urllib3\connectionpool.py", line 340, in _raise_timeout
    raise ReadTimeoutError(
urllib3.exceptions.ReadTimeoutError: HTTPSConnectionPool(host='zozo.jp', port=443): Read timed out. (read timeout=7.5)

During handling of the above exception, another exception occurred:

Traceback (most recent call last):
  File "./py/connect.py", line 186, in executeGetRequest
    res = requests.get(arrayList['crawlingurl'], timeout=(3.0, 7.5))
  File "C:\Users\waard\Desktop\my-app\py\env_v3.8.12\lib\site-packages\requests\api.py", line 75, in get
    return request('get', url, params=params, **kwargs)
  File "C:\Users\waard\Desktop\my-app\py\env_v3.8.12\lib\site-packages\requests\api.py", line 61, in request
    return session.request(method=method, url=url, **kwargs)
  File "C:\Users\waard\Desktop\my-app\py\env_v3.8.12\lib\site-packages\requests\sessions.py", line 529, in request
    resp = self.send(prep, **send_kwargs)
  File "C:\Users\waard\Desktop\my-app\py\env_v3.8.12\lib\site-packages\requests\sessions.py", line 645, in send
    r = adapter.send(request, **kwargs)
  File "C:\Users\waard\Desktop\my-app\py\env_v3.8.12\lib\site-packages\requests\adapters.py", line 532, in send
    raise ReadTimeout(e, request=request)
requests.exceptions.ReadTimeout: HTTPSConnectionPool(host='zozo.jp', port=443): Read timed out. (read timeout=7.5)

2022-01-14 16:37:20,042 <ERROR> :  occered at executeGetRequest <class 'requests.exceptions.ReadTimeout'>
2022-01-14 16:37:20,042 <ERROR> : Traceback (most recent call last):
  File "C:\Users\waard\Desktop\my-app\py\env_v3.8.12\lib\site-packages\urllib3\connectionpool.py", line 449, in _make_request
    six.raise_from(e, None)
  File "<string>", line 3, in raise_from
  File "C:\Users\waard\Desktop\my-app\py\env_v3.8.12\lib\site-packages\urllib3\connectionpool.py", line 444, in _make_request
    httplib_response = conn.getresponse()
  File "C:\Users\waard\anaconda3\lib\http\client.py", line 1348, in getresponse
    response.begin()
  File "C:\Users\waard\anaconda3\lib\http\client.py", line 316, in begin
    version, status, reason = self._read_status()
  File "C:\Users\waard\anaconda3\lib\http\client.py", line 277, in _read_status
    line = str(self.fp.readline(_MAXLINE + 1), "iso-8859-1")
  File "C:\Users\waard\anaconda3\lib\socket.py", line 669, in readinto
    return self._sock.recv_into(b)
  File "C:\Users\waard\anaconda3\lib\ssl.py", line 1241, in recv_into
    return self.read(nbytes, buffer)
  File "C:\Users\waard\anaconda3\lib\ssl.py", line 1099, in read
    return self._sslobj.read(len, buffer)
socket.timeout: The read operation timed out

During handling of the above exception, another exception occurred:

Traceback (most recent call last):
  File "C:\Users\waard\Desktop\my-app\py\env_v3.8.12\lib\site-packages\requests\adapters.py", line 440, in send
    resp = conn.urlopen(
  File "C:\Users\waard\Desktop\my-app\py\env_v3.8.12\lib\site-packages\urllib3\connectionpool.py", line 785, in urlopen
    retries = retries.increment(
  File "C:\Users\waard\Desktop\my-app\py\env_v3.8.12\lib\site-packages\urllib3\util\retry.py", line 550, in increment
    raise six.reraise(type(error), error, _stacktrace)
  File "C:\Users\waard\Desktop\my-app\py\env_v3.8.12\lib\site-packages\urllib3\packages\six.py", line 770, in reraise
    raise value
  File "C:\Users\waard\Desktop\my-app\py\env_v3.8.12\lib\site-packages\urllib3\connectionpool.py", line 703, in urlopen
    httplib_response = self._make_request(
  File "C:\Users\waard\Desktop\my-app\py\env_v3.8.12\lib\site-packages\urllib3\connectionpool.py", line 451, in _make_request
    self._raise_timeout(err=e, url=url, timeout_value=read_timeout)
  File "C:\Users\waard\Desktop\my-app\py\env_v3.8.12\lib\site-packages\urllib3\connectionpool.py", line 340, in _raise_timeout
    raise ReadTimeoutError(
urllib3.exceptions.ReadTimeoutError: HTTPSConnectionPool(host='zozo.jp', port=443): Read timed out. (read timeout=7.5)

During handling of the above exception, another exception occurred:

Traceback (most recent call last):
  File "./py/connect.py", line 186, in executeGetRequest
    res = requests.get(arrayList['crawlingurl'], timeout=(3.0, 7.5))
  File "C:\Users\waard\Desktop\my-app\py\env_v3.8.12\lib\site-packages\requests\api.py", line 75, in get
    return request('get', url, params=params, **kwargs)
  File "C:\Users\waard\Desktop\my-app\py\env_v3.8.12\lib\site-packages\requests\api.py", line 61, in request
    return session.request(method=method, url=url, **kwargs)
  File "C:\Users\waard\Desktop\my-app\py\env_v3.8.12\lib\site-packages\requests\sessions.py", line 529, in request
    resp = self.send(prep, **send_kwargs)
  File "C:\Users\waard\Desktop\my-app\py\env_v3.8.12\lib\site-packages\requests\sessions.py", line 645, in send
    r = adapter.send(request, **kwargs)
  File "C:\Users\waard\Desktop\my-app\py\env_v3.8.12\lib\site-packages\requests\adapters.py", line 532, in send
    raise ReadTimeout(e, request=request)
requests.exceptions.ReadTimeout: HTTPSConnectionPool(host='zozo.jp', port=443): Read timed out. (read timeout=7.5)

2022-01-14 16:37:27,625 <ERROR> :  occered at executeGetRequest <class 'requests.exceptions.ReadTimeout'>
2022-01-14 16:37:27,625 <ERROR> : Traceback (most recent call last):
  File "C:\Users\waard\Desktop\my-app\py\env_v3.8.12\lib\site-packages\urllib3\connectionpool.py", line 449, in _make_request
    six.raise_from(e, None)
  File "<string>", line 3, in raise_from
  File "C:\Users\waard\Desktop\my-app\py\env_v3.8.12\lib\site-packages\urllib3\connectionpool.py", line 444, in _make_request
    httplib_response = conn.getresponse()
  File "C:\Users\waard\anaconda3\lib\http\client.py", line 1348, in getresponse
    response.begin()
  File "C:\Users\waard\anaconda3\lib\http\client.py", line 316, in begin
    version, status, reason = self._read_status()
  File "C:\Users\waard\anaconda3\lib\http\client.py", line 277, in _read_status
    line = str(self.fp.readline(_MAXLINE + 1), "iso-8859-1")
  File "C:\Users\waard\anaconda3\lib\socket.py", line 669, in readinto
    return self._sock.recv_into(b)
  File "C:\Users\waard\anaconda3\lib\ssl.py", line 1241, in recv_into
    return self.read(nbytes, buffer)
  File "C:\Users\waard\anaconda3\lib\ssl.py", line 1099, in read
    return self._sslobj.read(len, buffer)
socket.timeout: The read operation timed out

During handling of the above exception, another exception occurred:

Traceback (most recent call last):
  File "C:\Users\waard\Desktop\my-app\py\env_v3.8.12\lib\site-packages\requests\adapters.py", line 440, in send
    resp = conn.urlopen(
  File "C:\Users\waard\Desktop\my-app\py\env_v3.8.12\lib\site-packages\urllib3\connectionpool.py", line 785, in urlopen
    retries = retries.increment(
  File "C:\Users\waard\Desktop\my-app\py\env_v3.8.12\lib\site-packages\urllib3\util\retry.py", line 550, in increment
    raise six.reraise(type(error), error, _stacktrace)
  File "C:\Users\waard\Desktop\my-app\py\env_v3.8.12\lib\site-packages\urllib3\packages\six.py", line 770, in reraise
    raise value
  File "C:\Users\waard\Desktop\my-app\py\env_v3.8.12\lib\site-packages\urllib3\connectionpool.py", line 703, in urlopen
    httplib_response = self._make_request(
  File "C:\Users\waard\Desktop\my-app\py\env_v3.8.12\lib\site-packages\urllib3\connectionpool.py", line 451, in _make_request
    self._raise_timeout(err=e, url=url, timeout_value=read_timeout)
  File "C:\Users\waard\Desktop\my-app\py\env_v3.8.12\lib\site-packages\urllib3\connectionpool.py", line 340, in _raise_timeout
    raise ReadTimeoutError(
urllib3.exceptions.ReadTimeoutError: HTTPSConnectionPool(host='zozo.jp', port=443): Read timed out. (read timeout=7.5)

During handling of the above exception, another exception occurred:

Traceback (most recent call last):
  File "./py/connect.py", line 186, in executeGetRequest
    res = requests.get(arrayList['crawlingurl'], timeout=(3.0, 7.5))
  File "C:\Users\waard\Desktop\my-app\py\env_v3.8.12\lib\site-packages\requests\api.py", line 75, in get
    return request('get', url, params=params, **kwargs)
  File "C:\Users\waard\Desktop\my-app\py\env_v3.8.12\lib\site-packages\requests\api.py", line 61, in request
    return session.request(method=method, url=url, **kwargs)
  File "C:\Users\waard\Desktop\my-app\py\env_v3.8.12\lib\site-packages\requests\sessions.py", line 529, in request
    resp = self.send(prep, **send_kwargs)
  File "C:\Users\waard\Desktop\my-app\py\env_v3.8.12\lib\site-packages\requests\sessions.py", line 645, in send
    r = adapter.send(request, **kwargs)
  File "C:\Users\waard\Desktop\my-app\py\env_v3.8.12\lib\site-packages\requests\adapters.py", line 532, in send
    raise ReadTimeout(e, request=request)
requests.exceptions.ReadTimeout: HTTPSConnectionPool(host='zozo.jp', port=443): Read timed out. (read timeout=7.5)

2022-01-14 16:37:27,625 <ERROR> :  occered at executeGetRequest Max retries exceeded with urlhttps://zozo.jp/brand/nike/shoes/sneakers/
2022-01-14 16:37:28,209 <ERROR> :  occered at executeGetRequest requests failed:https://www.jiji.com/jc/c?g=pol
2022-01-14 16:37:31,634 <ERROR> :  occered at executeGetRequest requests failed:https://www.jiji.com/jc/c?g=pol
2022-01-14 16:37:35,032 <ERROR> :  occered at executeGetRequest requests failed:https://www.jiji.com/jc/c?g=pol
2022-01-14 16:37:38,038 <ERROR> :  occered at executeGetRequest Max retries exceeded with urlhttps://www.jiji.com/jc/c?g=pol
2022-01-14 17:26:01,934 <ERROR> :  occered at executeGetRequest <class 'ValueError'>1
2022-01-14 17:26:01,934 <ERROR> : Traceback (most recent call last):
  File "./py/connect.py", line 194, in executeGetRequest
    root = lxml.html.fromstring(html)
  File "C:\Users\waard\Desktop\my-app\py\env_v3.8.12\lib\site-packages\lxml\html\__init__.py", line 875, in fromstring
    doc = document_fromstring(html, parser=parser, base_url=base_url, **kw)
  File "C:\Users\waard\Desktop\my-app\py\env_v3.8.12\lib\site-packages\lxml\html\__init__.py", line 761, in document_fromstring
    value = etree.fromstring(html, parser, **kw)
  File "src\lxml\etree.pyx", line 3252, in lxml.etree.fromstring
  File "src\lxml\parser.pxi", line 1907, in lxml.etree._parseMemoryDocument
ValueError: Unicode strings with encoding declaration are not supported. Please use bytes input or XML fragments without declaration.

2022-01-14 17:26:56,511 <ERROR> :  occered at executeGetRequest <class 'requests.exceptions.ReadTimeout'>
2022-01-14 17:26:56,511 <ERROR> : Traceback (most recent call last):
  File "C:\Users\waard\Desktop\my-app\py\env_v3.8.12\lib\site-packages\urllib3\connectionpool.py", line 449, in _make_request
    six.raise_from(e, None)
  File "<string>", line 3, in raise_from
  File "C:\Users\waard\Desktop\my-app\py\env_v3.8.12\lib\site-packages\urllib3\connectionpool.py", line 444, in _make_request
    httplib_response = conn.getresponse()
  File "C:\Users\waard\anaconda3\lib\http\client.py", line 1348, in getresponse
    response.begin()
  File "C:\Users\waard\anaconda3\lib\http\client.py", line 316, in begin
    version, status, reason = self._read_status()
  File "C:\Users\waard\anaconda3\lib\http\client.py", line 277, in _read_status
    line = str(self.fp.readline(_MAXLINE + 1), "iso-8859-1")
  File "C:\Users\waard\anaconda3\lib\socket.py", line 669, in readinto
    return self._sock.recv_into(b)
  File "C:\Users\waard\anaconda3\lib\ssl.py", line 1241, in recv_into
    return self.read(nbytes, buffer)
  File "C:\Users\waard\anaconda3\lib\ssl.py", line 1099, in read
    return self._sslobj.read(len, buffer)
socket.timeout: The read operation timed out

During handling of the above exception, another exception occurred:

Traceback (most recent call last):
  File "C:\Users\waard\Desktop\my-app\py\env_v3.8.12\lib\site-packages\requests\adapters.py", line 440, in send
    resp = conn.urlopen(
  File "C:\Users\waard\Desktop\my-app\py\env_v3.8.12\lib\site-packages\urllib3\connectionpool.py", line 785, in urlopen
    retries = retries.increment(
  File "C:\Users\waard\Desktop\my-app\py\env_v3.8.12\lib\site-packages\urllib3\util\retry.py", line 550, in increment
    raise six.reraise(type(error), error, _stacktrace)
  File "C:\Users\waard\Desktop\my-app\py\env_v3.8.12\lib\site-packages\urllib3\packages\six.py", line 770, in reraise
    raise value
  File "C:\Users\waard\Desktop\my-app\py\env_v3.8.12\lib\site-packages\urllib3\connectionpool.py", line 703, in urlopen
    httplib_response = self._make_request(
  File "C:\Users\waard\Desktop\my-app\py\env_v3.8.12\lib\site-packages\urllib3\connectionpool.py", line 451, in _make_request
    self._raise_timeout(err=e, url=url, timeout_value=read_timeout)
  File "C:\Users\waard\Desktop\my-app\py\env_v3.8.12\lib\site-packages\urllib3\connectionpool.py", line 340, in _raise_timeout
    raise ReadTimeoutError(
urllib3.exceptions.ReadTimeoutError: HTTPSConnectionPool(host='zozo.jp', port=443): Read timed out. (read timeout=7.5)

During handling of the above exception, another exception occurred:

Traceback (most recent call last):
  File "./py/connect.py", line 186, in executeGetRequest
    res = requests.get(arrayList['crawlingurl'], timeout=(3.0, 7.5))
  File "C:\Users\waard\Desktop\my-app\py\env_v3.8.12\lib\site-packages\requests\api.py", line 75, in get
    return request('get', url, params=params, **kwargs)
  File "C:\Users\waard\Desktop\my-app\py\env_v3.8.12\lib\site-packages\requests\api.py", line 61, in request
    return session.request(method=method, url=url, **kwargs)
  File "C:\Users\waard\Desktop\my-app\py\env_v3.8.12\lib\site-packages\requests\sessions.py", line 529, in request
    resp = self.send(prep, **send_kwargs)
  File "C:\Users\waard\Desktop\my-app\py\env_v3.8.12\lib\site-packages\requests\sessions.py", line 645, in send
    r = adapter.send(request, **kwargs)
  File "C:\Users\waard\Desktop\my-app\py\env_v3.8.12\lib\site-packages\requests\adapters.py", line 532, in send
    raise ReadTimeout(e, request=request)
requests.exceptions.ReadTimeout: HTTPSConnectionPool(host='zozo.jp', port=443): Read timed out. (read timeout=7.5)

2022-01-14 17:27:04,073 <ERROR> :  occered at executeGetRequest <class 'requests.exceptions.ReadTimeout'>
2022-01-14 17:27:04,073 <ERROR> : Traceback (most recent call last):
  File "C:\Users\waard\Desktop\my-app\py\env_v3.8.12\lib\site-packages\urllib3\connectionpool.py", line 449, in _make_request
    six.raise_from(e, None)
  File "<string>", line 3, in raise_from
  File "C:\Users\waard\Desktop\my-app\py\env_v3.8.12\lib\site-packages\urllib3\connectionpool.py", line 444, in _make_request
    httplib_response = conn.getresponse()
  File "C:\Users\waard\anaconda3\lib\http\client.py", line 1348, in getresponse
    response.begin()
  File "C:\Users\waard\anaconda3\lib\http\client.py", line 316, in begin
    version, status, reason = self._read_status()
  File "C:\Users\waard\anaconda3\lib\http\client.py", line 277, in _read_status
    line = str(self.fp.readline(_MAXLINE + 1), "iso-8859-1")
  File "C:\Users\waard\anaconda3\lib\socket.py", line 669, in readinto
    return self._sock.recv_into(b)
  File "C:\Users\waard\anaconda3\lib\ssl.py", line 1241, in recv_into
    return self.read(nbytes, buffer)
  File "C:\Users\waard\anaconda3\lib\ssl.py", line 1099, in read
    return self._sslobj.read(len, buffer)
socket.timeout: The read operation timed out

During handling of the above exception, another exception occurred:

Traceback (most recent call last):
  File "C:\Users\waard\Desktop\my-app\py\env_v3.8.12\lib\site-packages\requests\adapters.py", line 440, in send
    resp = conn.urlopen(
  File "C:\Users\waard\Desktop\my-app\py\env_v3.8.12\lib\site-packages\urllib3\connectionpool.py", line 785, in urlopen
    retries = retries.increment(
  File "C:\Users\waard\Desktop\my-app\py\env_v3.8.12\lib\site-packages\urllib3\util\retry.py", line 550, in increment
    raise six.reraise(type(error), error, _stacktrace)
  File "C:\Users\waard\Desktop\my-app\py\env_v3.8.12\lib\site-packages\urllib3\packages\six.py", line 770, in reraise
    raise value
  File "C:\Users\waard\Desktop\my-app\py\env_v3.8.12\lib\site-packages\urllib3\connectionpool.py", line 703, in urlopen
    httplib_response = self._make_request(
  File "C:\Users\waard\Desktop\my-app\py\env_v3.8.12\lib\site-packages\urllib3\connectionpool.py", line 451, in _make_request
    self._raise_timeout(err=e, url=url, timeout_value=read_timeout)
  File "C:\Users\waard\Desktop\my-app\py\env_v3.8.12\lib\site-packages\urllib3\connectionpool.py", line 340, in _raise_timeout
    raise ReadTimeoutError(
urllib3.exceptions.ReadTimeoutError: HTTPSConnectionPool(host='zozo.jp', port=443): Read timed out. (read timeout=7.5)

During handling of the above exception, another exception occurred:

Traceback (most recent call last):
  File "./py/connect.py", line 186, in executeGetRequest
    res = requests.get(arrayList['crawlingurl'], timeout=(3.0, 7.5))
  File "C:\Users\waard\Desktop\my-app\py\env_v3.8.12\lib\site-packages\requests\api.py", line 75, in get
    return request('get', url, params=params, **kwargs)
  File "C:\Users\waard\Desktop\my-app\py\env_v3.8.12\lib\site-packages\requests\api.py", line 61, in request
    return session.request(method=method, url=url, **kwargs)
  File "C:\Users\waard\Desktop\my-app\py\env_v3.8.12\lib\site-packages\requests\sessions.py", line 529, in request
    resp = self.send(prep, **send_kwargs)
  File "C:\Users\waard\Desktop\my-app\py\env_v3.8.12\lib\site-packages\requests\sessions.py", line 645, in send
    r = adapter.send(request, **kwargs)
  File "C:\Users\waard\Desktop\my-app\py\env_v3.8.12\lib\site-packages\requests\adapters.py", line 532, in send
    raise ReadTimeout(e, request=request)
requests.exceptions.ReadTimeout: HTTPSConnectionPool(host='zozo.jp', port=443): Read timed out. (read timeout=7.5)

2022-01-14 17:27:11,630 <ERROR> :  occered at executeGetRequest <class 'requests.exceptions.ReadTimeout'>
2022-01-14 17:27:11,630 <ERROR> : Traceback (most recent call last):
  File "C:\Users\waard\Desktop\my-app\py\env_v3.8.12\lib\site-packages\urllib3\connectionpool.py", line 449, in _make_request
    six.raise_from(e, None)
  File "<string>", line 3, in raise_from
  File "C:\Users\waard\Desktop\my-app\py\env_v3.8.12\lib\site-packages\urllib3\connectionpool.py", line 444, in _make_request
    httplib_response = conn.getresponse()
  File "C:\Users\waard\anaconda3\lib\http\client.py", line 1348, in getresponse
    response.begin()
  File "C:\Users\waard\anaconda3\lib\http\client.py", line 316, in begin
    version, status, reason = self._read_status()
  File "C:\Users\waard\anaconda3\lib\http\client.py", line 277, in _read_status
    line = str(self.fp.readline(_MAXLINE + 1), "iso-8859-1")
  File "C:\Users\waard\anaconda3\lib\socket.py", line 669, in readinto
    return self._sock.recv_into(b)
  File "C:\Users\waard\anaconda3\lib\ssl.py", line 1241, in recv_into
    return self.read(nbytes, buffer)
  File "C:\Users\waard\anaconda3\lib\ssl.py", line 1099, in read
    return self._sslobj.read(len, buffer)
socket.timeout: The read operation timed out

During handling of the above exception, another exception occurred:

Traceback (most recent call last):
  File "C:\Users\waard\Desktop\my-app\py\env_v3.8.12\lib\site-packages\requests\adapters.py", line 440, in send
    resp = conn.urlopen(
  File "C:\Users\waard\Desktop\my-app\py\env_v3.8.12\lib\site-packages\urllib3\connectionpool.py", line 785, in urlopen
    retries = retries.increment(
  File "C:\Users\waard\Desktop\my-app\py\env_v3.8.12\lib\site-packages\urllib3\util\retry.py", line 550, in increment
    raise six.reraise(type(error), error, _stacktrace)
  File "C:\Users\waard\Desktop\my-app\py\env_v3.8.12\lib\site-packages\urllib3\packages\six.py", line 770, in reraise
    raise value
  File "C:\Users\waard\Desktop\my-app\py\env_v3.8.12\lib\site-packages\urllib3\connectionpool.py", line 703, in urlopen
    httplib_response = self._make_request(
  File "C:\Users\waard\Desktop\my-app\py\env_v3.8.12\lib\site-packages\urllib3\connectionpool.py", line 451, in _make_request
    self._raise_timeout(err=e, url=url, timeout_value=read_timeout)
  File "C:\Users\waard\Desktop\my-app\py\env_v3.8.12\lib\site-packages\urllib3\connectionpool.py", line 340, in _raise_timeout
    raise ReadTimeoutError(
urllib3.exceptions.ReadTimeoutError: HTTPSConnectionPool(host='zozo.jp', port=443): Read timed out. (read timeout=7.5)

During handling of the above exception, another exception occurred:

Traceback (most recent call last):
  File "./py/connect.py", line 186, in executeGetRequest
    res = requests.get(arrayList['crawlingurl'], timeout=(3.0, 7.5))
  File "C:\Users\waard\Desktop\my-app\py\env_v3.8.12\lib\site-packages\requests\api.py", line 75, in get
    return request('get', url, params=params, **kwargs)
  File "C:\Users\waard\Desktop\my-app\py\env_v3.8.12\lib\site-packages\requests\api.py", line 61, in request
    return session.request(method=method, url=url, **kwargs)
  File "C:\Users\waard\Desktop\my-app\py\env_v3.8.12\lib\site-packages\requests\sessions.py", line 529, in request
    resp = self.send(prep, **send_kwargs)
  File "C:\Users\waard\Desktop\my-app\py\env_v3.8.12\lib\site-packages\requests\sessions.py", line 645, in send
    r = adapter.send(request, **kwargs)
  File "C:\Users\waard\Desktop\my-app\py\env_v3.8.12\lib\site-packages\requests\adapters.py", line 532, in send
    raise ReadTimeout(e, request=request)
requests.exceptions.ReadTimeout: HTTPSConnectionPool(host='zozo.jp', port=443): Read timed out. (read timeout=7.5)

2022-01-14 17:27:11,630 <ERROR> :  occered at executeGetRequest Max retries exceeded with urlhttps://zozo.jp/brand/nike/shoes/sneakers/
2022-01-14 17:27:12,148 <ERROR> :  occered at executeGetRequest requests failed:https://www.jiji.com/jc/c?g=pol
2022-01-14 17:27:15,433 <ERROR> :  occered at executeGetRequest requests failed:https://www.jiji.com/jc/c?g=pol
2022-01-14 17:27:18,828 <ERROR> :  occered at executeGetRequest requests failed:https://www.jiji.com/jc/c?g=pol
2022-01-14 17:27:21,841 <ERROR> :  occered at executeGetRequest Max retries exceeded with urlhttps://www.jiji.com/jc/c?g=pol
2022-01-14 17:32:16,719 <ERROR> :  occered at executeGetRequest <class 'ValueError'>1
2022-01-14 17:32:16,719 <ERROR> : Traceback (most recent call last):
  File "./py/connect.py", line 194, in executeGetRequest
    root = lxml.html.fromstring(html)
  File "C:\Users\waard\Desktop\my-app\py\env_v3.8.12\lib\site-packages\lxml\html\__init__.py", line 875, in fromstring
    doc = document_fromstring(html, parser=parser, base_url=base_url, **kw)
  File "C:\Users\waard\Desktop\my-app\py\env_v3.8.12\lib\site-packages\lxml\html\__init__.py", line 761, in document_fromstring
    value = etree.fromstring(html, parser, **kw)
  File "src\lxml\etree.pyx", line 3252, in lxml.etree.fromstring
  File "src\lxml\parser.pxi", line 1907, in lxml.etree._parseMemoryDocument
ValueError: Unicode strings with encoding declaration are not supported. Please use bytes input or XML fragments without declaration.

2022-01-14 17:33:07,862 <ERROR> :  occered at executeGetRequest <class 'requests.exceptions.ReadTimeout'>
2022-01-14 17:33:07,862 <ERROR> : Traceback (most recent call last):
  File "C:\Users\waard\Desktop\my-app\py\env_v3.8.12\lib\site-packages\urllib3\connectionpool.py", line 449, in _make_request
    six.raise_from(e, None)
  File "<string>", line 3, in raise_from
  File "C:\Users\waard\Desktop\my-app\py\env_v3.8.12\lib\site-packages\urllib3\connectionpool.py", line 444, in _make_request
    httplib_response = conn.getresponse()
  File "C:\Users\waard\anaconda3\lib\http\client.py", line 1348, in getresponse
    response.begin()
  File "C:\Users\waard\anaconda3\lib\http\client.py", line 316, in begin
    version, status, reason = self._read_status()
  File "C:\Users\waard\anaconda3\lib\http\client.py", line 277, in _read_status
    line = str(self.fp.readline(_MAXLINE + 1), "iso-8859-1")
  File "C:\Users\waard\anaconda3\lib\socket.py", line 669, in readinto
    return self._sock.recv_into(b)
  File "C:\Users\waard\anaconda3\lib\ssl.py", line 1241, in recv_into
    return self.read(nbytes, buffer)
  File "C:\Users\waard\anaconda3\lib\ssl.py", line 1099, in read
    return self._sslobj.read(len, buffer)
socket.timeout: The read operation timed out

During handling of the above exception, another exception occurred:

Traceback (most recent call last):
  File "C:\Users\waard\Desktop\my-app\py\env_v3.8.12\lib\site-packages\requests\adapters.py", line 440, in send
    resp = conn.urlopen(
  File "C:\Users\waard\Desktop\my-app\py\env_v3.8.12\lib\site-packages\urllib3\connectionpool.py", line 785, in urlopen
    retries = retries.increment(
  File "C:\Users\waard\Desktop\my-app\py\env_v3.8.12\lib\site-packages\urllib3\util\retry.py", line 550, in increment
    raise six.reraise(type(error), error, _stacktrace)
  File "C:\Users\waard\Desktop\my-app\py\env_v3.8.12\lib\site-packages\urllib3\packages\six.py", line 770, in reraise
    raise value
  File "C:\Users\waard\Desktop\my-app\py\env_v3.8.12\lib\site-packages\urllib3\connectionpool.py", line 703, in urlopen
    httplib_response = self._make_request(
  File "C:\Users\waard\Desktop\my-app\py\env_v3.8.12\lib\site-packages\urllib3\connectionpool.py", line 451, in _make_request
    self._raise_timeout(err=e, url=url, timeout_value=read_timeout)
  File "C:\Users\waard\Desktop\my-app\py\env_v3.8.12\lib\site-packages\urllib3\connectionpool.py", line 340, in _raise_timeout
    raise ReadTimeoutError(
urllib3.exceptions.ReadTimeoutError: HTTPSConnectionPool(host='zozo.jp', port=443): Read timed out. (read timeout=7.5)

During handling of the above exception, another exception occurred:

Traceback (most recent call last):
  File "./py/connect.py", line 186, in executeGetRequest
    res = requests.get(arrayList['crawlingurl'], timeout=(3.0, 7.5))
  File "C:\Users\waard\Desktop\my-app\py\env_v3.8.12\lib\site-packages\requests\api.py", line 75, in get
    return request('get', url, params=params, **kwargs)
  File "C:\Users\waard\Desktop\my-app\py\env_v3.8.12\lib\site-packages\requests\api.py", line 61, in request
    return session.request(method=method, url=url, **kwargs)
  File "C:\Users\waard\Desktop\my-app\py\env_v3.8.12\lib\site-packages\requests\sessions.py", line 529, in request
    resp = self.send(prep, **send_kwargs)
  File "C:\Users\waard\Desktop\my-app\py\env_v3.8.12\lib\site-packages\requests\sessions.py", line 645, in send
    r = adapter.send(request, **kwargs)
  File "C:\Users\waard\Desktop\my-app\py\env_v3.8.12\lib\site-packages\requests\adapters.py", line 532, in send
    raise ReadTimeout(e, request=request)
requests.exceptions.ReadTimeout: HTTPSConnectionPool(host='zozo.jp', port=443): Read timed out. (read timeout=7.5)

2022-01-14 17:33:15,421 <ERROR> :  occered at executeGetRequest <class 'requests.exceptions.ReadTimeout'>
2022-01-14 17:33:15,421 <ERROR> : Traceback (most recent call last):
  File "C:\Users\waard\Desktop\my-app\py\env_v3.8.12\lib\site-packages\urllib3\connectionpool.py", line 449, in _make_request
    six.raise_from(e, None)
  File "<string>", line 3, in raise_from
  File "C:\Users\waard\Desktop\my-app\py\env_v3.8.12\lib\site-packages\urllib3\connectionpool.py", line 444, in _make_request
    httplib_response = conn.getresponse()
  File "C:\Users\waard\anaconda3\lib\http\client.py", line 1348, in getresponse
    response.begin()
  File "C:\Users\waard\anaconda3\lib\http\client.py", line 316, in begin
    version, status, reason = self._read_status()
  File "C:\Users\waard\anaconda3\lib\http\client.py", line 277, in _read_status
    line = str(self.fp.readline(_MAXLINE + 1), "iso-8859-1")
  File "C:\Users\waard\anaconda3\lib\socket.py", line 669, in readinto
    return self._sock.recv_into(b)
  File "C:\Users\waard\anaconda3\lib\ssl.py", line 1241, in recv_into
    return self.read(nbytes, buffer)
  File "C:\Users\waard\anaconda3\lib\ssl.py", line 1099, in read
    return self._sslobj.read(len, buffer)
socket.timeout: The read operation timed out

During handling of the above exception, another exception occurred:

Traceback (most recent call last):
  File "C:\Users\waard\Desktop\my-app\py\env_v3.8.12\lib\site-packages\requests\adapters.py", line 440, in send
    resp = conn.urlopen(
  File "C:\Users\waard\Desktop\my-app\py\env_v3.8.12\lib\site-packages\urllib3\connectionpool.py", line 785, in urlopen
    retries = retries.increment(
  File "C:\Users\waard\Desktop\my-app\py\env_v3.8.12\lib\site-packages\urllib3\util\retry.py", line 550, in increment
    raise six.reraise(type(error), error, _stacktrace)
  File "C:\Users\waard\Desktop\my-app\py\env_v3.8.12\lib\site-packages\urllib3\packages\six.py", line 770, in reraise
    raise value
  File "C:\Users\waard\Desktop\my-app\py\env_v3.8.12\lib\site-packages\urllib3\connectionpool.py", line 703, in urlopen
    httplib_response = self._make_request(
  File "C:\Users\waard\Desktop\my-app\py\env_v3.8.12\lib\site-packages\urllib3\connectionpool.py", line 451, in _make_request
    self._raise_timeout(err=e, url=url, timeout_value=read_timeout)
  File "C:\Users\waard\Desktop\my-app\py\env_v3.8.12\lib\site-packages\urllib3\connectionpool.py", line 340, in _raise_timeout
    raise ReadTimeoutError(
urllib3.exceptions.ReadTimeoutError: HTTPSConnectionPool(host='zozo.jp', port=443): Read timed out. (read timeout=7.5)

During handling of the above exception, another exception occurred:

Traceback (most recent call last):
  File "./py/connect.py", line 186, in executeGetRequest
    res = requests.get(arrayList['crawlingurl'], timeout=(3.0, 7.5))
  File "C:\Users\waard\Desktop\my-app\py\env_v3.8.12\lib\site-packages\requests\api.py", line 75, in get
    return request('get', url, params=params, **kwargs)
  File "C:\Users\waard\Desktop\my-app\py\env_v3.8.12\lib\site-packages\requests\api.py", line 61, in request
    return session.request(method=method, url=url, **kwargs)
  File "C:\Users\waard\Desktop\my-app\py\env_v3.8.12\lib\site-packages\requests\sessions.py", line 529, in request
    resp = self.send(prep, **send_kwargs)
  File "C:\Users\waard\Desktop\my-app\py\env_v3.8.12\lib\site-packages\requests\sessions.py", line 645, in send
    r = adapter.send(request, **kwargs)
  File "C:\Users\waard\Desktop\my-app\py\env_v3.8.12\lib\site-packages\requests\adapters.py", line 532, in send
    raise ReadTimeout(e, request=request)
requests.exceptions.ReadTimeout: HTTPSConnectionPool(host='zozo.jp', port=443): Read timed out. (read timeout=7.5)

2022-01-14 17:33:22,980 <ERROR> :  occered at executeGetRequest <class 'requests.exceptions.ReadTimeout'>
2022-01-14 17:33:22,980 <ERROR> : Traceback (most recent call last):
  File "C:\Users\waard\Desktop\my-app\py\env_v3.8.12\lib\site-packages\urllib3\connectionpool.py", line 449, in _make_request
    six.raise_from(e, None)
  File "<string>", line 3, in raise_from
  File "C:\Users\waard\Desktop\my-app\py\env_v3.8.12\lib\site-packages\urllib3\connectionpool.py", line 444, in _make_request
    httplib_response = conn.getresponse()
  File "C:\Users\waard\anaconda3\lib\http\client.py", line 1348, in getresponse
    response.begin()
  File "C:\Users\waard\anaconda3\lib\http\client.py", line 316, in begin
    version, status, reason = self._read_status()
  File "C:\Users\waard\anaconda3\lib\http\client.py", line 277, in _read_status
    line = str(self.fp.readline(_MAXLINE + 1), "iso-8859-1")
  File "C:\Users\waard\anaconda3\lib\socket.py", line 669, in readinto
    return self._sock.recv_into(b)
  File "C:\Users\waard\anaconda3\lib\ssl.py", line 1241, in recv_into
    return self.read(nbytes, buffer)
  File "C:\Users\waard\anaconda3\lib\ssl.py", line 1099, in read
    return self._sslobj.read(len, buffer)
socket.timeout: The read operation timed out

During handling of the above exception, another exception occurred:

Traceback (most recent call last):
  File "C:\Users\waard\Desktop\my-app\py\env_v3.8.12\lib\site-packages\requests\adapters.py", line 440, in send
    resp = conn.urlopen(
  File "C:\Users\waard\Desktop\my-app\py\env_v3.8.12\lib\site-packages\urllib3\connectionpool.py", line 785, in urlopen
    retries = retries.increment(
  File "C:\Users\waard\Desktop\my-app\py\env_v3.8.12\lib\site-packages\urllib3\util\retry.py", line 550, in increment
    raise six.reraise(type(error), error, _stacktrace)
  File "C:\Users\waard\Desktop\my-app\py\env_v3.8.12\lib\site-packages\urllib3\packages\six.py", line 770, in reraise
    raise value
  File "C:\Users\waard\Desktop\my-app\py\env_v3.8.12\lib\site-packages\urllib3\connectionpool.py", line 703, in urlopen
    httplib_response = self._make_request(
  File "C:\Users\waard\Desktop\my-app\py\env_v3.8.12\lib\site-packages\urllib3\connectionpool.py", line 451, in _make_request
    self._raise_timeout(err=e, url=url, timeout_value=read_timeout)
  File "C:\Users\waard\Desktop\my-app\py\env_v3.8.12\lib\site-packages\urllib3\connectionpool.py", line 340, in _raise_timeout
    raise ReadTimeoutError(
urllib3.exceptions.ReadTimeoutError: HTTPSConnectionPool(host='zozo.jp', port=443): Read timed out. (read timeout=7.5)

During handling of the above exception, another exception occurred:

Traceback (most recent call last):
  File "./py/connect.py", line 186, in executeGetRequest
    res = requests.get(arrayList['crawlingurl'], timeout=(3.0, 7.5))
  File "C:\Users\waard\Desktop\my-app\py\env_v3.8.12\lib\site-packages\requests\api.py", line 75, in get
    return request('get', url, params=params, **kwargs)
  File "C:\Users\waard\Desktop\my-app\py\env_v3.8.12\lib\site-packages\requests\api.py", line 61, in request
    return session.request(method=method, url=url, **kwargs)
  File "C:\Users\waard\Desktop\my-app\py\env_v3.8.12\lib\site-packages\requests\sessions.py", line 529, in request
    resp = self.send(prep, **send_kwargs)
  File "C:\Users\waard\Desktop\my-app\py\env_v3.8.12\lib\site-packages\requests\sessions.py", line 645, in send
    r = adapter.send(request, **kwargs)
  File "C:\Users\waard\Desktop\my-app\py\env_v3.8.12\lib\site-packages\requests\adapters.py", line 532, in send
    raise ReadTimeout(e, request=request)
requests.exceptions.ReadTimeout: HTTPSConnectionPool(host='zozo.jp', port=443): Read timed out. (read timeout=7.5)

2022-01-14 17:33:22,980 <ERROR> :  occered at executeGetRequest Max retries exceeded with urlhttps://zozo.jp/brand/nike/shoes/sneakers/
2022-01-14 17:33:23,498 <ERROR> :  occered at executeGetRequest requests failed:https://www.jiji.com/jc/c?g=pol
2022-01-14 17:33:26,890 <ERROR> :  occered at executeGetRequest requests failed:https://www.jiji.com/jc/c?g=pol
2022-01-14 17:33:30,205 <ERROR> :  occered at executeGetRequest requests failed:https://www.jiji.com/jc/c?g=pol
2022-01-14 17:33:33,232 <ERROR> :  occered at executeGetRequest Max retries exceeded with urlhttps://www.jiji.com/jc/c?g=pol
2022-01-14 17:34:27,611 <ERROR> :  occered at executeGetRequest <class 'ValueError'>1
2022-01-14 17:34:27,611 <ERROR> : Traceback (most recent call last):
  File "./py/connect.py", line 194, in executeGetRequest
    root = lxml.html.fromstring(html)
  File "C:\Users\waard\Desktop\my-app\py\env_v3.8.12\lib\site-packages\lxml\html\__init__.py", line 875, in fromstring
    doc = document_fromstring(html, parser=parser, base_url=base_url, **kw)
  File "C:\Users\waard\Desktop\my-app\py\env_v3.8.12\lib\site-packages\lxml\html\__init__.py", line 761, in document_fromstring
    value = etree.fromstring(html, parser, **kw)
  File "src\lxml\etree.pyx", line 3252, in lxml.etree.fromstring
  File "src\lxml\parser.pxi", line 1907, in lxml.etree._parseMemoryDocument
ValueError: Unicode strings with encoding declaration are not supported. Please use bytes input or XML fragments without declaration.

2022-01-14 17:35:27,088 <ERROR> :  occered at executeGetRequest <class 'requests.exceptions.ReadTimeout'>
2022-01-14 17:35:27,088 <ERROR> : Traceback (most recent call last):
  File "C:\Users\waard\Desktop\my-app\py\env_v3.8.12\lib\site-packages\urllib3\connectionpool.py", line 449, in _make_request
    six.raise_from(e, None)
  File "<string>", line 3, in raise_from
  File "C:\Users\waard\Desktop\my-app\py\env_v3.8.12\lib\site-packages\urllib3\connectionpool.py", line 444, in _make_request
    httplib_response = conn.getresponse()
  File "C:\Users\waard\anaconda3\lib\http\client.py", line 1348, in getresponse
    response.begin()
  File "C:\Users\waard\anaconda3\lib\http\client.py", line 316, in begin
    version, status, reason = self._read_status()
  File "C:\Users\waard\anaconda3\lib\http\client.py", line 277, in _read_status
    line = str(self.fp.readline(_MAXLINE + 1), "iso-8859-1")
  File "C:\Users\waard\anaconda3\lib\socket.py", line 669, in readinto
    return self._sock.recv_into(b)
  File "C:\Users\waard\anaconda3\lib\ssl.py", line 1241, in recv_into
    return self.read(nbytes, buffer)
  File "C:\Users\waard\anaconda3\lib\ssl.py", line 1099, in read
    return self._sslobj.read(len, buffer)
socket.timeout: The read operation timed out

During handling of the above exception, another exception occurred:

Traceback (most recent call last):
  File "C:\Users\waard\Desktop\my-app\py\env_v3.8.12\lib\site-packages\requests\adapters.py", line 440, in send
    resp = conn.urlopen(
  File "C:\Users\waard\Desktop\my-app\py\env_v3.8.12\lib\site-packages\urllib3\connectionpool.py", line 785, in urlopen
    retries = retries.increment(
  File "C:\Users\waard\Desktop\my-app\py\env_v3.8.12\lib\site-packages\urllib3\util\retry.py", line 550, in increment
    raise six.reraise(type(error), error, _stacktrace)
  File "C:\Users\waard\Desktop\my-app\py\env_v3.8.12\lib\site-packages\urllib3\packages\six.py", line 770, in reraise
    raise value
  File "C:\Users\waard\Desktop\my-app\py\env_v3.8.12\lib\site-packages\urllib3\connectionpool.py", line 703, in urlopen
    httplib_response = self._make_request(
  File "C:\Users\waard\Desktop\my-app\py\env_v3.8.12\lib\site-packages\urllib3\connectionpool.py", line 451, in _make_request
    self._raise_timeout(err=e, url=url, timeout_value=read_timeout)
  File "C:\Users\waard\Desktop\my-app\py\env_v3.8.12\lib\site-packages\urllib3\connectionpool.py", line 340, in _raise_timeout
    raise ReadTimeoutError(
urllib3.exceptions.ReadTimeoutError: HTTPSConnectionPool(host='zozo.jp', port=443): Read timed out. (read timeout=7.5)

During handling of the above exception, another exception occurred:

Traceback (most recent call last):
  File "./py/connect.py", line 186, in executeGetRequest
    res = requests.get(arrayList['crawlingurl'], timeout=(3.0, 7.5))
  File "C:\Users\waard\Desktop\my-app\py\env_v3.8.12\lib\site-packages\requests\api.py", line 75, in get
    return request('get', url, params=params, **kwargs)
  File "C:\Users\waard\Desktop\my-app\py\env_v3.8.12\lib\site-packages\requests\api.py", line 61, in request
    return session.request(method=method, url=url, **kwargs)
  File "C:\Users\waard\Desktop\my-app\py\env_v3.8.12\lib\site-packages\requests\sessions.py", line 529, in request
    resp = self.send(prep, **send_kwargs)
  File "C:\Users\waard\Desktop\my-app\py\env_v3.8.12\lib\site-packages\requests\sessions.py", line 645, in send
    r = adapter.send(request, **kwargs)
  File "C:\Users\waard\Desktop\my-app\py\env_v3.8.12\lib\site-packages\requests\adapters.py", line 532, in send
    raise ReadTimeout(e, request=request)
requests.exceptions.ReadTimeout: HTTPSConnectionPool(host='zozo.jp', port=443): Read timed out. (read timeout=7.5)

2022-01-14 17:35:34,641 <ERROR> :  occered at executeGetRequest <class 'requests.exceptions.ReadTimeout'>
2022-01-14 17:35:34,641 <ERROR> : Traceback (most recent call last):
  File "C:\Users\waard\Desktop\my-app\py\env_v3.8.12\lib\site-packages\urllib3\connectionpool.py", line 449, in _make_request
    six.raise_from(e, None)
  File "<string>", line 3, in raise_from
  File "C:\Users\waard\Desktop\my-app\py\env_v3.8.12\lib\site-packages\urllib3\connectionpool.py", line 444, in _make_request
    httplib_response = conn.getresponse()
  File "C:\Users\waard\anaconda3\lib\http\client.py", line 1348, in getresponse
    response.begin()
  File "C:\Users\waard\anaconda3\lib\http\client.py", line 316, in begin
    version, status, reason = self._read_status()
  File "C:\Users\waard\anaconda3\lib\http\client.py", line 277, in _read_status
    line = str(self.fp.readline(_MAXLINE + 1), "iso-8859-1")
  File "C:\Users\waard\anaconda3\lib\socket.py", line 669, in readinto
    return self._sock.recv_into(b)
  File "C:\Users\waard\anaconda3\lib\ssl.py", line 1241, in recv_into
    return self.read(nbytes, buffer)
  File "C:\Users\waard\anaconda3\lib\ssl.py", line 1099, in read
    return self._sslobj.read(len, buffer)
socket.timeout: The read operation timed out

During handling of the above exception, another exception occurred:

Traceback (most recent call last):
  File "C:\Users\waard\Desktop\my-app\py\env_v3.8.12\lib\site-packages\requests\adapters.py", line 440, in send
    resp = conn.urlopen(
  File "C:\Users\waard\Desktop\my-app\py\env_v3.8.12\lib\site-packages\urllib3\connectionpool.py", line 785, in urlopen
    retries = retries.increment(
  File "C:\Users\waard\Desktop\my-app\py\env_v3.8.12\lib\site-packages\urllib3\util\retry.py", line 550, in increment
    raise six.reraise(type(error), error, _stacktrace)
  File "C:\Users\waard\Desktop\my-app\py\env_v3.8.12\lib\site-packages\urllib3\packages\six.py", line 770, in reraise
    raise value
  File "C:\Users\waard\Desktop\my-app\py\env_v3.8.12\lib\site-packages\urllib3\connectionpool.py", line 703, in urlopen
    httplib_response = self._make_request(
  File "C:\Users\waard\Desktop\my-app\py\env_v3.8.12\lib\site-packages\urllib3\connectionpool.py", line 451, in _make_request
    self._raise_timeout(err=e, url=url, timeout_value=read_timeout)
  File "C:\Users\waard\Desktop\my-app\py\env_v3.8.12\lib\site-packages\urllib3\connectionpool.py", line 340, in _raise_timeout
    raise ReadTimeoutError(
urllib3.exceptions.ReadTimeoutError: HTTPSConnectionPool(host='zozo.jp', port=443): Read timed out. (read timeout=7.5)

During handling of the above exception, another exception occurred:

Traceback (most recent call last):
  File "./py/connect.py", line 186, in executeGetRequest
    res = requests.get(arrayList['crawlingurl'], timeout=(3.0, 7.5))
  File "C:\Users\waard\Desktop\my-app\py\env_v3.8.12\lib\site-packages\requests\api.py", line 75, in get
    return request('get', url, params=params, **kwargs)
  File "C:\Users\waard\Desktop\my-app\py\env_v3.8.12\lib\site-packages\requests\api.py", line 61, in request
    return session.request(method=method, url=url, **kwargs)
  File "C:\Users\waard\Desktop\my-app\py\env_v3.8.12\lib\site-packages\requests\sessions.py", line 529, in request
    resp = self.send(prep, **send_kwargs)
  File "C:\Users\waard\Desktop\my-app\py\env_v3.8.12\lib\site-packages\requests\sessions.py", line 645, in send
    r = adapter.send(request, **kwargs)
  File "C:\Users\waard\Desktop\my-app\py\env_v3.8.12\lib\site-packages\requests\adapters.py", line 532, in send
    raise ReadTimeout(e, request=request)
requests.exceptions.ReadTimeout: HTTPSConnectionPool(host='zozo.jp', port=443): Read timed out. (read timeout=7.5)

2022-01-14 17:35:42,189 <ERROR> :  occered at executeGetRequest <class 'requests.exceptions.ReadTimeout'>
2022-01-14 17:35:42,189 <ERROR> : Traceback (most recent call last):
  File "C:\Users\waard\Desktop\my-app\py\env_v3.8.12\lib\site-packages\urllib3\connectionpool.py", line 449, in _make_request
    six.raise_from(e, None)
  File "<string>", line 3, in raise_from
  File "C:\Users\waard\Desktop\my-app\py\env_v3.8.12\lib\site-packages\urllib3\connectionpool.py", line 444, in _make_request
    httplib_response = conn.getresponse()
  File "C:\Users\waard\anaconda3\lib\http\client.py", line 1348, in getresponse
    response.begin()
  File "C:\Users\waard\anaconda3\lib\http\client.py", line 316, in begin
    version, status, reason = self._read_status()
  File "C:\Users\waard\anaconda3\lib\http\client.py", line 277, in _read_status
    line = str(self.fp.readline(_MAXLINE + 1), "iso-8859-1")
  File "C:\Users\waard\anaconda3\lib\socket.py", line 669, in readinto
    return self._sock.recv_into(b)
  File "C:\Users\waard\anaconda3\lib\ssl.py", line 1241, in recv_into
    return self.read(nbytes, buffer)
  File "C:\Users\waard\anaconda3\lib\ssl.py", line 1099, in read
    return self._sslobj.read(len, buffer)
socket.timeout: The read operation timed out

During handling of the above exception, another exception occurred:

Traceback (most recent call last):
  File "C:\Users\waard\Desktop\my-app\py\env_v3.8.12\lib\site-packages\requests\adapters.py", line 440, in send
    resp = conn.urlopen(
  File "C:\Users\waard\Desktop\my-app\py\env_v3.8.12\lib\site-packages\urllib3\connectionpool.py", line 785, in urlopen
    retries = retries.increment(
  File "C:\Users\waard\Desktop\my-app\py\env_v3.8.12\lib\site-packages\urllib3\util\retry.py", line 550, in increment
    raise six.reraise(type(error), error, _stacktrace)
  File "C:\Users\waard\Desktop\my-app\py\env_v3.8.12\lib\site-packages\urllib3\packages\six.py", line 770, in reraise
    raise value
  File "C:\Users\waard\Desktop\my-app\py\env_v3.8.12\lib\site-packages\urllib3\connectionpool.py", line 703, in urlopen
    httplib_response = self._make_request(
  File "C:\Users\waard\Desktop\my-app\py\env_v3.8.12\lib\site-packages\urllib3\connectionpool.py", line 451, in _make_request
    self._raise_timeout(err=e, url=url, timeout_value=read_timeout)
  File "C:\Users\waard\Desktop\my-app\py\env_v3.8.12\lib\site-packages\urllib3\connectionpool.py", line 340, in _raise_timeout
    raise ReadTimeoutError(
urllib3.exceptions.ReadTimeoutError: HTTPSConnectionPool(host='zozo.jp', port=443): Read timed out. (read timeout=7.5)

During handling of the above exception, another exception occurred:

Traceback (most recent call last):
  File "./py/connect.py", line 186, in executeGetRequest
    res = requests.get(arrayList['crawlingurl'], timeout=(3.0, 7.5))
  File "C:\Users\waard\Desktop\my-app\py\env_v3.8.12\lib\site-packages\requests\api.py", line 75, in get
    return request('get', url, params=params, **kwargs)
  File "C:\Users\waard\Desktop\my-app\py\env_v3.8.12\lib\site-packages\requests\api.py", line 61, in request
    return session.request(method=method, url=url, **kwargs)
  File "C:\Users\waard\Desktop\my-app\py\env_v3.8.12\lib\site-packages\requests\sessions.py", line 529, in request
    resp = self.send(prep, **send_kwargs)
  File "C:\Users\waard\Desktop\my-app\py\env_v3.8.12\lib\site-packages\requests\sessions.py", line 645, in send
    r = adapter.send(request, **kwargs)
  File "C:\Users\waard\Desktop\my-app\py\env_v3.8.12\lib\site-packages\requests\adapters.py", line 532, in send
    raise ReadTimeout(e, request=request)
requests.exceptions.ReadTimeout: HTTPSConnectionPool(host='zozo.jp', port=443): Read timed out. (read timeout=7.5)

2022-01-14 17:35:42,190 <ERROR> :  occered at executeGetRequest Max retries exceeded with urlhttps://zozo.jp/brand/nike/shoes/sneakers/
2022-01-14 17:35:43,060 <ERROR> :  occered at executeGetRequest requests failed:https://www.jiji.com/jc/c?g=pol
2022-01-14 17:35:46,451 <ERROR> :  occered at executeGetRequest requests failed:https://www.jiji.com/jc/c?g=pol
2022-01-14 17:35:49,799 <ERROR> :  occered at executeGetRequest requests failed:https://www.jiji.com/jc/c?g=pol
2022-01-14 17:35:53,320 <ERROR> :  occered at executeGetRequest Max retries exceeded with urlhttps://www.jiji.com/jc/c?g=pol
